Workbook

Sheet MASTER -YEARLY
B2: THÁNG | C2: THU NHẬP | H2: CHI PHÍ | N2: CÒN LẠI | P2: PHÂN BỔ | S2: TỔNG TÍCH LŨY & ĐẦU TƯ | T2: TIỀN MẶT CÒN LẠI
C3: CK | D3: VK | E3: SUBO | F3: SUGI | G3: TỔNG THU | H3: CHUNG | I3: CK | J3: VK | K3: SUBO | L3: SUGI | M3: TỔNG CHI | P3: TIẾT KIỆM (DỰ PHÒNG) | Q3: ĐẦU TƯ DCA (3 QUỸ) | R3: QUỸ BẮT ĐÁY
B4: 1 | C4: ='T1 - MASTER'!D4 | D4: ='T1 - MASTER'!D5 | E4: ='T1 - MASTER'!D6 | F4: ='T1 - MASTER'!D7 | G4: =SUM(C4:F4) | H4: ='T1 - MASTER'!D13 | I4: ='T1 - MASTER'!D16 | J4: ='T1 - MASTER'!D18 | K4: ='T1 - MASTER'!D14 | L4: ='T1 - MASTER'!D15 | M4: =SUM(H4:L4) | N4: =G4-M4 | O4: =N4/G4 | P4: =MAX(0, N4 - Q4 - R4) | Q4: 12000000 | R4: =MAX(0, MIN(4000000, N4-Q4)) | S4: =P4+Q4+R4 | T4: =N4-S4
B5: 2 | C5: ='T2 - MASTER'!D4 | D5: ='T2 - MASTER'!D5 | E5: ='T2 - MASTER'!D6 | F5: ='T2 - MASTER'!D7 | G5: =SUM(C5:F5) | H5: ='T2 - MASTER'!D13 | I5: ='T2 - MASTER'!D16 | J5: ='T2 - MASTER'!D18 | K5: ='T2 - MASTER'!D14 | L5: ='T2 - MASTER'!D15 | M5: =SUM(H5:L5) | N5: =G5-M5 | O5: =N5/G5 | P5: =MAX(0, N5 - Q5 - R5) | Q5: 12000000 | R5: 4000000 | S5: =P5+Q5+R5 | T5: =N5-S5
B6: 3 | C6: ='T3 - MASTER'!D4 | D6: ='T3 - MASTER'!D5 | E6: ='T3 - MASTER'!D6 | F6: ='T3 - MASTER'!D7 | G6: =SUM(C6:F6) | H6: ='T3 - MASTER'!D13 | I6: ='T3 - MASTER'!D16 | J6: ='T3 - MASTER'!D18 | K6: ='T3 - MASTER'!D14 | L6: ='T3 - MASTER'!D15 | M6: =SUM(H6:L6) | N6: =G6-M6 | O6: =N6/G6 | P6: =MAX(0, N6 - Q6 - R6) | Q6: 12000000 | R6: 4000000 | S6: =P6+Q6+R6 | T6: =N6-S6
B7: 4 | C7: ='T4 - MASTER'!D4 | D7: ='T4 - MASTER'!D5 | E7: ='T4 - MASTER'!D6 | F7: ='T4 - MASTER'!D7 | G7: =SUM(C7:F7) | H7: ='T4 - MASTER'!D13 | I7: ='T4 - MASTER'!D16 | J7: ='T4 - MASTER'!D18 | K7: ='T4 - MASTER'!D14 | L7: ='T4 - MASTER'!D15 | M7: =SUM(H7:L7) | N7: =G7-M7 | O7: =N7/G7 | P7: =MAX(0, N7 - Q7 - R7) | Q7: 12000000 | R7: 4000000 | S7: =P7+Q7+R7 | T7: =N7-S7
B8: 5 | C8: ='T5 - MASTER'!D4 | D8: ='T5 - MASTER'!D5 | E8: ='T5 - MASTER'!D6 | F8: ='T5 - MASTER'!D7 | G8: =SUM(C8:F8) | H8: ='T5 - MASTER'!D13 | I8: ='T5 - MASTER'!D16 | J8: ='T5 - MASTER'!D18 | K8: ='T5 - MASTER'!D14 | L8: ='T5 - MASTER'!D15 | M8: =SUM(H8:L8) | N8: =G8-M8 | O8: =N8/G8 | P8: =MAX(0, N8 - Q8 - R8) | Q8: 12000000 | R8: 4000000 | S8: =P8+Q8+R8 | T8: =N8-S8
B9: 6 | C9: ='T6 - MASTER'!D4 | D9: ='T6 - MASTER'!D5 | E9: ='T6 - MASTER'!D6 | F9: ='T6 - MASTER'!D7 | G9: =SUM(C9:F9) | H9: ='T6 - MASTER'!D13 | I9: ='T6 - MASTER'!D16 | J9: ='T6 - MASTER'!D18 | K9: ='T6 - MASTER'!D14 | L9: ='T6 - MASTER'!D15 | M9: =SUM(H9:L9) | N9: =G9-M9 | O9: =N9/G9 | P9: =MAX(0, N9 - Q9 - R9) | Q9: 12000000 | R9: 4000000 | S9: =P9+Q9+R9 | T9: =N9-S9
B10: 7 | C10: ='T7 - MASTER'!D4 | D10: ='T7 - MASTER'!D5 | E10: ='T7 - MASTER'!D6 | F10: ='T7 - MASTER'!D7 | G10: =SUM(C10:F10) | H10: ='T7 - MASTER'!D13 | I10: ='T7 - MASTER'!D16 | J10: ='T7 - MASTER'!D18 | K10: ='T7 - MASTER'!D14 | L10: ='T7 - MASTER'!D15 | M10: =SUM(H10:L10) | N10: =G10-M10 | O10: =N10/G10 | P10: =MAX(0, N10 - Q10 - R10) | Q10: 0 | R10: 2970000 | S10: =P10+Q10+R10 | T10: =N10-S10
B11: 8 | C11: ='T8 - MASTER'!D4 | D11: ='T8 - MASTER'!D5 | E11: ='T8 - MASTER'!D6 | F11: ='T8 - MASTER'!D7 | G11: =SUM(C11:F11) | H11: ='T8 - MASTER'!D13 | I11: ='T8 - MASTER'!D16 | J11: ='T8 - MASTER'!D18 | K11: ='T8 - MASTER'!D14 | L11: ='T8 - MASTER'!D15 | M11: =SUM(H11:L11) | N11: =G11-M11 | O11: =N11/G11 | P11: =MAX(0, N11 - Q11 - R11) | Q11: 12000000 | R11: 4000000 | S11: =P11+Q11+R11 | T11: =N11-S11
B12: 9 | C12: ='T9 - MASTER'!D4 | D12: ='T9 - MASTER'!D5 | E12: ='T9 - MASTER'!D6 | F12: ='T9 - MASTER'!D7 | G12: =SUM(C12:F12) | H12: ='T9 - MASTER'!D13 | I12: ='T9 - MASTER'!D16 | J12: ='T9 - MASTER'!D18 | K12: ='T9 - MASTER'!D14 | L12: ='T9 - MASTER'!D15 | M12: =SUM(H12:L12) | N12: =G12-M12 | O12: =N12/G12 | P12: =MAX(0, N12 - Q12 - R12) | Q12: 12000000 | R12: 1606000 | S12: =P12+Q12+R12 | T12: =N12-S12
B13: 10 | C13: ='T10 - MASTER'!D4 | D13: ='T10 - MASTER'!D5 | E13: ='T10 - MASTER'!D6 | F13: ='T10 - MASTER'!D7 | G13: =SUM(C13:F13) | H13: ='T10 - MASTER'!D13 | I13: ='T10 - MASTER'!D16 | J13: ='T10 - MASTER'!D18 | K13: ='T10 - MASTER'!D14 | L13: ='T10 - MASTER'!D15 | M13: =SUM(H13:L13) | N13: =G13-M13 | O13: =IF(G13>0, N13/G13, 0) | P13: =MAX(0, N13 - Q13 - R13) | Q13: 12000000 | R13: 4000000 | S13: =P13+Q13+R13 | T13: =N13-S13
B14: 11 | C14: ='T11 - MASTER'!D4 | D14: ='T11 - MASTER'!D5 | E14: ='T11 - MASTER'!D6 | F14: ='T11 - MASTER'!D7 | G14: =SUM(C14:F14) | H14: ='T11 - MASTER'!D13 | I14: ='T11 - MASTER'!D16 | J14: ='T11 - MASTER'!D18 | K14: ='T11 - MASTER'!D14 | L14: ='T11 - MASTER'!D15 | M14: =SUM(H14:L14) | N14: =G14-M14 | O14: =IFERROR(N14/G14, 0) | P14: =MAX(0, N14 - Q14 - R14) | Q14: 0 | R14: 0 | S14: =P14+Q14+R14 | T14: =N14-S14
B15: 12 | C15: ='T12 - MASTER'!D4 | D15: ='T12 - MASTER'!D5 | E15: ='T12 - MASTER'!D6 | F15: ='T12 - MASTER'!D7 | G15: =SUM(C15:F15) | H15: ='T12 - MASTER'!D13 | I15: ='T12 - MASTER'!D16 | J15: ='T12 - MASTER'!D18 | K15: ='T12 - MASTER'!D14 | L15: ='T12 - MASTER'!D15 | M15: =SUM(H15:L15) | N15: =G15-M15 | O15: =IFERROR(N15/G15, 0) | P15: =MAX(0, N15 - Q15 - R15) | Q15: 0 | R15: 0 | S15: =P15+Q15+R15 | T15: =N15-S15
B16: TỔNG (80% TÍCH LŨY) | C16: =SUM(C4:C15) | D16: =SUM(D4:D15) | E16: =SUM(E4:E15) | F16: =SUM(F4:F15) | G16: =SUM(G4:G15) | H16: =SUM(H4:H15) | I16: =SUM(I4:I15) | J16: =SUM(J4:J15) | ... M16: =SUM(M4:M15) | N16: =SUM(N4:N15)*80% | O16: =IFERROR(N16/G16, 0) | P16: =SUM(P4:P15) | Q16: =SUM(Q4:Q15) | R16: =SUM(R4:R15) | S16: =SUM(S4:S15) | T16: =SUM(T4:T15)
B17: TIỀN CÒN LẠI (20%) | N17: =SUM(N4:N15)*20% | O17: =IFERROR(N17/G16, 0)
B18: TỔNG THẶNG DƯ (100%) | N18: =SUM(N4:N15) | O18: =IFERROR(N18/G16, 0)

Sheet T1 - MASTER
B1: 46023
A3: I | B3: THU NHẬP | C3: 1 | D3: =SUM(D4:D7)
A4: 1 | B4: ck | D4: =SUM(E4:H4) | E4: 37700000 | F4: 8000000 | G4: 6500000 | H4: 0
A5: 2 | B5: vk | D5: =SUM(E5:H5) | E5: 26435000 | F5: 200000 | G5: 420000 | H5: 0
A6: 3 | B6: Subo | D6: =SUM(E6:H6) | E6: 720000 | F6: 0 | G6: 0 | H6: 0
A7: 4 | B7: Sugi | D7: =SUM(E7:H7) | E7: 0 | F7: 0 | G7: 0 | H7: 0
A8: II | B8: TIẾT KIỆM | C8: 0.3 | D8: =D3*C8 | I8: CÒN LẠI | K8: =D3-D11
B9: TK thực tế | I9: CP ĐÃ TRỪ NHƯNG CHƯA ĐÓNG | J9: HỌC PHÍ | K9: 9350000
A10: III | B10: CHI PHÍ | C10: 0.7 | D10: =D3*C10 | J10: ĐIỆN THOẠI | K10: 3000000
B11: CP Thực tế | D11: =SUM(D12,D16,D18) | I11: actual | K11: =SUM(K8:K10)
A12: 1 | B12: Chi phí chung gia đình | C12: =IFERROR(D12/D11, 0) | D12: =SUM(D13:D15)
A13: a | B13: Chi phí chung | C13: =IFERROR(D13/$D$10, 0) | D13: ='T1 - DETAIL'!I2
A14: b | B14: Chi phí riêng subo | C14: =IFERROR(D14/$D$10, 0) | D14: ='T1 - DETAIL'!I5
A15: c | B15: chi phí riêng sugi | C15: =IFERROR(D15/$D$10, 0) | D15: ='T1 - DETAIL'!I6
A16: 2 | B16: Chi phí riêng ck (20%) | C16: =IFERROR(D16/D11, 0) | D16: ='T1 - DETAIL'!I3 | F16: =B17-D16
B17: =20%*D10
A18: 3 | B18: Chi phí riêng vk (20%) | C18: =IFERROR(D18/D11, 0) | D18: ='T1 - DETAIL'!I4 | F18: =B19-D18
B19: =20%*D10

Sheet T1 - DETAIL
H1: Tổng | I1: =SUM(F4:F1025) | J1: ăn uống | K1: vui chơi | L1: công việc | M1: học tập | N1: đồ dùng GĐ | O1: Phí tiện ích | P1: làm đẹp | Q1: y tế | R1: event | S1: nợ
B2: Ngày | C2: nội dung | D2: Hạng mục | E2: Phân loại | F2: Số Tiền | H2: Chung | I2: =SUM(J2:S2) | J2: =SUMIFS($F$4:$F$844 , $D$4:$D$844, "Ăn uống", $E$4:$E$844, "chung") | K2: =SUMIFS($F$4:$F$844 , $D$4:$D$844, "vui chơi", $E$4:$E$844, "chung") | L2: =SUMIFS($F$4:$F$844 , $D$4:$D$844, "Công việc", $E$4:$E$844, "chung") | M2: =SUMIFS($F$4:$F$844 , $D$4:$D$844, "học tập", $E$4:$E$844, "chung") | N2: =SUMIFS($F$4:$F$844 , $D$4:$D$844, "đồ dùng GĐ", $E$4:$E$844, "chung") | O2: =SUMIFS($F$4:$F$844 , $D$4:$D$844, "phí tiện ích", $E$4:$E$844, "chung") | P2: =SUMIFS($F$4:$F$844 , $D$4:$D$844, "Làm đẹp", $E$4:$E$844, "chung") | Q2: =SUMIFS($F$4:$F$844 , $D$4:$D$844, "Y tế", $E$4:$E$844, "chung") | R2: =SUMIFS($F$4:$F$844 , $D$4:$D$844, "event", $E$4:$E$844, "chung") | S2: =SUMIFS($F$4:$F$844 , $D$4:$D$844, "Nợ", $E$4:$E$844, "chung")
F3: =SUM(F4:F844) | H3: Chồng | I3: =SUM(J3:S3) | J3: =SUMIFS($F$4:$F$844 , $D$4:$D$844, "Ăn uống", $E$4:$E$844, "chồng") | K3: =SUMIFS($F$4:$F$844 , $D$4:$D$844, "vui chơi", $E$4:$E$844, "chồng") | L3: =SUMIFS($F$4:$F$844 , $D$4:$D$844, "Công việc", $E$4:$E$844, "chồng") | M3: =SUMIFS($F$4:$F$844 , $D$4:$D$844, "học tập", $E$4:$E$844, "chồng") | N3: =SUMIFS($F$4:$F$844 , $D$4:$D$844, "đồ dùng GĐ", $E$4:$E$844, "chồng") | O3: =SUMIFS($F$4:$F$844 , $D$4:$D$844, "phí tiện ích", $E$4:$E$844, "chồng") | P3: =SUMIFS($F$4:$F$844 , $D$4:$D$844, "Làm đẹp", $E$4:$E$844, "chồng") | Q3: =SUMIFS($F$4:$F$844 , $D$4:$D$844, "Y tế", $E$4:$E$844, "chồng") | R3: =SUMIFS($F$4:$F$844 , $D$4:$D$844, "event", $E$4:$E$844, "chồng") | S3: =SUMIFS($F$4:$F$844 , $D$4:$D$844, "Nợ", $E$4:$E$844, "chồng")
B4: 45658 | C4: điện thoại | D4: Nợ | E4: vợ | F4: 3000000 | H4: vợ | I4: =SUM(J4:S4) | J4: =SUMIFS($F$4:$F$844 , $D$4:$D$844, "Ăn uống", $E$4:$E$844, "vợ") | K4: =SUMIFS($F$4:$F$844 , $D$4:$D$844, "vui chơi", $E$4:$E$844, "vợ") | L4: =SUMIFS($F$4:$F$844 , $D$4:$D$844, "Công việc", $E$4:$E$844, "vợ") | M4: =SUMIFS($F$4:$F$844 , $D$4:$D$844, "học tập", $E$4:$E$844, "vợ") | N4: =SUMIFS($F$4:$F$844 , $D$4:$D$844, "đồ dùng GĐ", $E$4:$E$844, "vợ") | O4: =SUMIFS($F$4:$F$844 , $D$4:$D$844, "phí tiện ích", $E$4:$E$844, "vợ") | P4: =SUMIFS($F$4:$F$844 , $D$4:$D$844, "Làm đẹp", $E$4:$E$844, "vợ") | Q4: =SUMIFS($F$4:$F$844 , $D$4:$D$844, "Y tế", $E$4:$E$844, "vợ") | R4: =SUMIFS($F$4:$F$844 , $D$4:$D$844, "event", $E$4:$E$844, "vợ") | S4: =SUMIFS($F$4:$F$844 , $D$4:$D$844, "Nợ", $E$4:$E$844, "vợ")
C5: học phí subo | D5: học tập | E5: SUBO | F5: 9350000 | H5: subo | I5: =SUM(J5:S5) | J5: =SUMIFS($F$4:$F$844 , $D$4:$D$844, "Ăn uống", $E$4:$E$844, "SUBO") | K5: =SUMIFS($F$4:$F$844 , $D$4:$D$844, "vui chơi", $E$4:$E$844, "SUBO") | L5: =SUMIFS($F$4:$F$844 , $D$4:$D$844, "Công việc", $E$4:$E$844, "SUBO") | M5: =SUMIFS($F$4:$F$844 , $D$4:$D$844, "học tập", $E$4:$E$844, "SUBO") | N5: =SUMIFS($F$4:$F$844 , $D$4:$D$844, "đồ dùng GĐ", $E$4:$E$844, "SUBO") | O5: =SUMIFS($F$4:$F$844 , $D$4:$D$844, "phí tiện ích", $E$4:$E$844, "SUBO") | P5: =SUMIFS($F$4:$F$844 , $D$4:$D$844, "Làm đẹp", $E$4:$E$844, "SUBO") | Q5: =SUMIFS($F$4:$F$844 , $D$4:$D$844, "Y tế", $E$4:$E$844, "SUBO") | R5: =SUMIFS($F$4:$F$844 , $D$4:$D$844, "event", $E$4:$E$844, "SUBO") | S5: =SUMIFS($F$4:$F$844 , $D$4:$D$844, "Nợ", $E$4:$E$844, "SUBO")
C6: cơm tấm, cơm cá hồi, busan | D6: Ăn uống | E6: Chung | F6: =286000+141000+144000 | G6: vp | H6: sugi | I6: =SUM(J6:S6) | J6: =SUMIFS($F$4:$F$844 , $D$4:$D$844, "Ăn uống", $E$4:$E$844, "SUGI") | K6: =SUMIFS($F$4:$F$844 , $D$4:$D$844, "vui chơi", $E$4:$E$844, "SUGI") | L6: =SUMIFS($F$4:$F$844 , $D$4:$D$844, "Công việc", $E$4:$E$844, "SUGI") | M6: =SUMIFS($F$4:$F$844 , $D$4:$D$844, "học tập", $E$4:$E$844, "SUGI") | N6: =SUMIFS($F$4:$F$844 , $D$4:$D$844, "đồ dùng GĐ", $E$4:$E$844, "SUGI") | O6: =SUMIFS($F$4:$F$844 , $D$4:$D$844, "phí tiện ích", $E$4:$E$844, "SUGI") | P6: =SUMIFS($F$4:$F$844 , $D$4:$D$844, "Làm đẹp", $E$4:$E$844, "SUGI") | Q6: =SUMIFS($F$4:$F$844 , $D$4:$D$844, "Y tế", $E$4:$E$844, "SUGI") | R6: =SUMIFS($F$4:$F$844 , $D$4:$D$844, "event", $E$4:$E$844, "SUGI") | S6: =SUMIFS($F$4:$F$844 , $D$4:$D$844, "Nợ", $E$4:$E$844, "SUGI")
C7: shopee ( túi hút chân ko, móc đồ, mocz treo QA, kệ giày, đồ chà,..) | D7: đồ dùng GĐ | E7: Chung | F7: =101000+162000+37000+15000+107000 | G7: vp | I7: sum | J7: =SUM(J2:J6) | K7: =SUM(K2:K6) | L7: =SUM(L2:L6) | M7: =SUM(M2:M6) | N7: =SUM(N2:N6) | O7: =SUM(O2:O6) | P7: =SUM(P2:P6) | Q7: =SUM(Q2:Q6) | ... S7: =SUM(S2:S6)
C8: shopee quần áo sugi | D8: Làm đẹp | E8: SUGI | F8: =163000+511000 | G8: vp | I8: % | J8: =J7/$I$1 | K8: =K7/$I$1 | L8: =L7/$I$1 | M8: =M7/$I$1 | N8: =N7/$I$1 | O8: =O7/$I$1 | P8: =P7/$I$1 | Q8: =Q7/$I$1 | ... S8: =S7/$I$1
C9: trái cây | D9: Ăn uống | E9: Chung | F9: 950000
C10: ăn sáng | D10: Ăn uống | E10: Chung | F10: 95000
C11: gà | D11: Ăn uống | E11: Chung | F11: 390000 | V11: =J4/14
C12: vòi nước | D12: đồ dùng GĐ | E12: Chung | F12: 160000
C13: tiền đt | D13: phí tiện ích | E13: vợ | F13: 45000 | V13: =J3/14
C14: keo | D14: đồ dùng GĐ | E14: Chung | F14: 39000 | G14: vp
C15: sữa | D15: Ăn uống | E15: Chung | F15: 477000 | G15: vp
B16: 46024 | C16: ăn sáng, nước dừa | D16: Ăn uống | E16: Chung | F16: =190000+86000
C17: heo quay | D17: Ăn uống | E17: Chung | F17: 83000 | G17: vp
C18: hành ngò... | D18: Ăn uống | E18: Chung | F18: =37000+16000 | G18: vp-done
C19: tắc | D19: Ăn uống | E19: Chung | F19: 7000
B20: 46025 | C20: bún, bánh mì | D20: Ăn uống | E20: Chung | F20: 56000 | G20: vp
C21: cây xà phòng | D21: vui chơi | E21: SUBO | F21: 39000 | G21: vp
C22: cơm bắc | D22: Ăn uống | E22: Chung | F22: 277000
C23: hoa, lá giang | D23: Ăn uống | E23: Chung | F23: 40000
C24: trái cây | D24: Ăn uống | E24: Chung | F24: 297000
C25: phí cc | D25: phí tiện ích | E25: Chung | F25: 432000
C26: shopee đồ sửa nhà | D26: đồ dùng GĐ | E26: Chung | F26: 182000 | G26: vp-done
B27: 4/1 | C27: tiniworld | D27: vui chơi | E27: SUBO | F27: 162000 | G27: vp
C28: emart | D28: Ăn uống | E28: Chung | F28: =45000+815000 | G28: vp
B29: 5/1 | C29: shopee đồ sắp xếp trong nhà (túi đựng đồ) | D29: đồ dùng GĐ | E29: Chung | F29: 86000 | G29: vp
C30: rau chợ | D30: Ăn uống | E30: Chung | F30: 30000
B31: 6/1 | C31: vé máy bay | D31: phí tiện ích | E31: Chung | F31: 1296000 | G31: vp-done
C32: rau chợ | D32: Ăn uống | E32: Chung | F32: 29000
C33: que test đường | D33: Y tế | E33: Chung | F33: 158000 | G33: vp
B34: 7/1 | C34: chat gpt | D34: Công việc | E34: Chung | F34: =44213000-43624000 | G34: vp
C35: trái cây | D35: Ăn uống | E35: Chung | F35: 1320000
C36: rau | D36: Ăn uống | E36: Chung | F36: 45000
B37: 8/1 | C37: đóng thuế ck | D37: Nợ | E37: chồng | F37: 3000000
C38: rau | D38: Ăn uống | E38: Chung | F38: 43000
B39: 9/1 | C39: shinhan | D39: Nợ | E39: chồng | F39: 2250000
C40: khám thai | D40: Y tế | E40: Chung | F40: =910000+1110000
...

Sheet T8 - MASTER
B1: 46023
A3: I | B3: THU NHẬP | C3: 1 | D3: =SUM(D4:D7)
B4: ck | D4: =SUM(E4:H4) | E4: 45454000 | F4: 8000000 | G4: 0 | H4: 0
A5: 2 | B5: vk | D5: =SUM(E5:H5) | E5: 30000000 | F5: 5000000 | G5: 0 | H5: 0
A6: 3 | B6: Subo | D6: =SUM(E6:H6) | F6: 0 | G6: 0 | H6: 0
A7: 4 | B7: Sugi | D7: =SUM(E7:H7) | E7: 0 | F7: 0 | G7: 0 | H7: 0
A8: II | B8: TIẾT KIỆM | C8: 0.3 | D8: =D3*C8 | I8: CÒN LẠI | K8: =D3-D11
B9: TK thực tế | I9: CP ĐÃ TRỪ NHƯNG CHƯA ĐÓNG | J9: HỌC PHÍ
A10: III | B10: CHI PHÍ | C10: 0.7 | D10: =D3*C10 | J10: ĐIỆN THOẠI
B11: CP Thực tế | D11: =SUM(D12,D16,D18) | K11: =SUM(K8:K10)
A12: 1 | B12: Chi phí chung gia đình | C12: =IFERROR(D12/D11, 0) | D12: =SUM(D13:D15)
A13: a | B13: Chi phí chung | C13: =IFERROR(D13/$D$10, 0) | D13: ='T8 - DETAIL'!I2
A14: b | B14: Chi phí riêng subo | C14: =IFERROR(D14/$D$10, 0) | D14: ='T8 - DETAIL'!I5
A15: c | B15: chi phí riêng sugi | C15: =IFERROR(D15/$D$10, 0) | D15: ='T8 - DETAIL'!I6
A16: 2 | B16: Chi phí riêng ck (30%) | C16: =IFERROR(D16/D11, 0) | D16: ='T8 - DETAIL'!I3
B17: =30%*D10
A18: 3 | B18: Chi phí riêng vk (30%) | C18: =IFERROR(D18/D11, 0) | D18: ='T8 - DETAIL'!I4
B19: =30%*D10

Sheet T9 - MASTER
B1: 46023
A3: I | B3: THU NHẬP | C3: 1 | D3: =SUM(D4:D7)
A4: 1 | B4: ck | D4: =SUM(E4:H4) | E4: 45500000 | F4: 8000000 | G4: 0 | H4: 0
A5: 2 | B5: vk | D5: =SUM(E5:H5) | E5: 34100000 | F5: 18000000 | G5: 0 | H5: 0
A6: 3 | B6: Subo | D6: =SUM(E6:H6) | E6: 2000000 | F6: 2000000 | G6: 0 | H6: 0
A7: 4 | B7: Sugi | D7: =SUM(E7:H7) | E7: 0 | F7: 0 | G7: 0 | H7: 0
A8: II | B8: TIẾT KIỆM | C8: 0.3 | D8: =D3*C8 | I8: CÒN LẠI | K8: =D3-D11
B9: TK thực tế | I9: CP ĐÃ TRỪ NHƯNG CHƯA ĐÓNG | J9: HỌC PHÍ
A10: III | B10: CHI PHÍ | C10: 0.7 | D10: =D3*C10 | J10: ĐIỆN THOẠI
B11: CP Thực tế | D11: =SUM(D12,D16,D18) | K11: =SUM(K8:K10)
A12: 1 | B12: Chi phí chung gia đình | C12: =IFERROR(D12/D11, 0) | D12: =SUM(D13:D15)
A13: a | B13: Chi phí chung | C13: =IFERROR(D13/$D$10, 0) | D13: ='T9 - DETAIL'!I2
A14: b | B14: Chi phí riêng subo | C14: =IFERROR(D14/$D$10, 0) | D14: ='T9 - DETAIL'!I5
A15: c | B15: chi phí riêng sugi | C15: =IFERROR(D15/$D$10, 0) | D15: ='T9 - DETAIL'!I6
A16: 2 | B16: Chi phí riêng ck (30%) | C16: =IFERROR(D16/D11, 0) | D16: ='T9 - DETAIL'!I3
B17: =30%*D10
A18: 3 | B18: Chi phí riêng vk (30%) | C18: =IFERROR(D18/D11, 0) | D18: ='T9 - DETAIL'!I4
B19: =30%*D10

Sheet T11 - MASTER
B1: 46023
A3: I | B3: THU NHẬP | C3: 1 | D3: =SUM(D4:D7)
A4: 1 | B4: ck | D4: =SUM(E4:H4) | E4: 0 | F4: 0 | G4: 0 | H4: 0
A5: 2 | B5: vk | D5: =SUM(E5:H5) | E5: 0 | F5: 0 | G5: 0 | H5: 0
A6: 3 | B6: Subo | D6: =SUM(E6:H6) | E6: 0 | F6: 0 | G6: 0 | H6: 0
A7: 4 | B7: Sugi | D7: =SUM(E7:H7) | E7: 0 | F7: 0 | G7: 0 | H7: 0
A8: II | B8: TIẾT KIỆM | C8: 0.3 | D8: =D3*C8 | I8: CÒN LẠI | K8: =D3-D11
B9: TK thực tế | I9: CP ĐÃ TRỪ NHƯNG CHƯA ĐÓNG | J9: HỌC PHÍ
A10: III | B10: CHI PHÍ | C10: 0.7 | D10: =D3*C10 | J10: ĐIỆN THOẠI
B11: CP Thực tế | D11: =SUM(D12,D16,D18) | K11: =SUM(K8:K10)
A12: 1 | B12: Chi phí chung gia đình | C12: =IFERROR(D12/D11, 0) | D12: =SUM(D13:D15)
A13: a | B13: Chi phí chung | C13: =IFERROR(D13/$D$10, 0) | D13: ='T11 - DETAIL'!I2
A14: b | B14: Chi phí riêng subo | C14: =IFERROR(D14/$D$10, 0) | D14: ='T11 - DETAIL'!I5
A15: c | B15: chi phí riêng sugi | C15: =IFERROR(D15/$D$10, 0) | D15: ='T11 - DETAIL'!I6
A16: 2 | B16: Chi phí riêng ck (30%) | C16: =IFERROR(D16/D11, 0) | D16: ='T11 - DETAIL'!I3
B17: =30%*D10
A18: 3 | B18: Chi phí riêng vk (30%) | C18: =IFERROR(D18/D11, 0) | D18: ='T11 - DETAIL'!I4
B19: =30%*D10

Sheet T10 - MASTER
B1: 46296
A3: I | B3: THU NHẬP | C3: 1 | D3: =SUM(D4:D7)
A4: 1 | B4: ck | D4: =SUM(E4:H4) | E4: 45000000 | F4: 0 | G4: 0 | H4: 0
A5: 2 | B5: vk | D5: =SUM(E5:H5) | E5: 34283000 | F5: 500000 | G5: 0 | H5: 0
A6: 3 | B6: Subo | D6: =SUM(E6:H6) | E6: 0 | F6: 0 | G6: 0 | H6: 0
A7: 4 | B7: Sugi | D7: =SUM(E7:H7) | E7: 0 | F7: 0 | G7: 0 | H7: 0
A8: II | B8: TIẾT KIỆM | C8: 0.3 | D8: =D3*C8 | I8: CÒN LẠI | K8: =D3-D11
B9: TK thực tế | I9: CP ĐÃ TRỪ NHƯNG CHƯA ĐÓNG | J9: HỌC PHÍ
A10: III | B10: CHI PHÍ | C10: 0.7 | D10: =D3*C10 | J10: ĐIỆN THOẠI
B11: CP Thực tế | D11: =SUM(D12,D16,D18) | K11: =SUM(K8:K10)
A12: 1 | B12: Chi phí chung gia đình | C12: =IFERROR(D12/D11, 0) | D12: =SUM(D13:D15)
A13: a | B13: Chi phí chung | C13: =IFERROR(D13/$D$10, 0) | D13: ='T10 - DETAIL'!I2
A14: b | B14: Chi phí riêng subo | C14: =IFERROR(D14/$D$10, 0) | D14: ='T10 - DETAIL'!I5
A15: c | B15: chi phí riêng sugi | C15: =IFERROR(D15/$D$10, 0) | D15: ='T10 - DETAIL'!I7
A16: 2 | B16: Chi phí riêng ck (30%) | C16: =IFERROR(D16/D11, 0) | D16: ='T10 - DETAIL'!I3
B17: =30%*D10
A18: 3 | B18: Chi phí riêng vk (30%) | C18: =IFERROR(D18/D11, 0) | D18: ='T10 - DETAIL'!I4
B19: =30%*D10

Sheet T12 - MASTER
B1: 46357
A3: I | B3: THU NHẬP | C3: 1 | D3: =SUM(D4:D7)
A4: 1 | B4: ck | D4: =SUM(E4:H4) | E4: 0 | F4: 0 | G4: 0 | H4: 0
A5: 2 | B5: vk | D5: =SUM(E5:H5) | E5: 0 | F5: 0 | G5: 0 | H5: 0
A6: 3 | B6: Subo | D6: =SUM(E6:H6) | E6: 0 | F6: 0 | G6: 0 | H6: 0
A7: 4 | B7: Sugi | D7: =SUM(E7:H7) | E7: 0 | F7: 0 | G7: 0 | H7: 0
A8: II | B8: TIẾT KIỆM | C8: 0.3 | D8: =D3*C8 | I8: CÒN LẠI | K8: =D3-D11
B9: TK thực tế | I9: CP ĐÃ TRỪ NHƯNG CHƯA ĐÓNG | J9: HỌC PHÍ
A10: III | B10: CHI PHÍ | C10: 0.7 | D10: =D3*C10 | J10: ĐIỆN THOẠI
B11: CP Thực tế | D11: =SUM(D12,D16,D18) | K11: =SUM(K8:K10)
A12: 1 | B12: Chi phí chung gia đình | C12: =IFERROR(D12/D11, 0) | D12: =SUM(D13:D15)
A13: a | B13: Chi phí chung | C13: =IFERROR(D13/$D$10, 0) | D13: ='T12 - DETAIL'!I2
A14: b | B14: Chi phí riêng subo | C14: =IFERROR(D14/$D$10, 0) | D14: ='T12 - DETAIL'!I5
A15: c | B15: chi phí riêng sugi | C15: =IFERROR(D15/$D$10, 0) | D15: ='T12 - DETAIL'!I6
A16: 2 | B16: Chi phí riêng ck (30%) | C16: =IFERROR(D16/D11, 0) | D16: ='T12 - DETAIL'!I3
B17: =30%*D10
A18: 3 | B18: Chi phí riêng vk (30%) | C18: =IFERROR(D18/D11, 0) | D18: ='T12 - DETAIL'!I4
B19: =30%*D10

Sheet T8 - DETAIL
H1: Tổng | I1: =SUM(F4:F984) | J1: ăn uống | K1: vui chơi | L1: công việc | M1: học tập | N1: đồ dùng GĐ | O1: Phí tiện ích | P1: làm đẹp | Q1: y tế | R1: event | S1: nợ
B2: Ngày | C2: nội dung | D2: Hạng mục | E2: Phân loại | F2: Số Tiền | H2: Chung | I2: =SUM(J2:S2) | J2: =SUMIFS($F$4:$F$803 , $D$4:$D$803, "Ăn uống", $E$4:$E$803, "chung") | K2: =SUMIFS($F$4:$F$803 , $D$4:$D$803, "vui chơi", $E$4:$E$803, "chung") | L2: =SUMIFS($F$4:$F$803 , $D$4:$D$803, "Công việc", $E$4:$E$803, "chung") | M2: =SUMIFS($F$4:$F$803 , $D$4:$D$803, "học tập", $E$4:$E$803, "chung") | N2: =SUMIFS($F$4:$F$803 , $D$4:$D$803, "đồ dùng GĐ", $E$4:$E$803, "chung") | O2: =SUMIFS($F$4:$F$803 , $D$4:$D$803, "phí tiện ích", $E$4:$E$803, "chung") | P2: =SUMIFS($F$4:$F$803 , $D$4:$D$803, "Làm đẹp", $E$4:$E$803, "chung") | Q2: =SUMIFS($F$4:$F$803 , $D$4:$D$803, "Y tế", $E$4:$E$803, "chung") | R2: =SUMIFS($F$4:$F$803 , $D$4:$D$803, "event", $E$4:$E$803, "chung") | S2: =SUMIFS($F$4:$F$803 , $D$4:$D$803, "Nợ", $E$4:$E$803, "chung")
F3: =SUM(F4:F803) | H3: Chồng | I3: =SUM(J3:S3) | J3: =SUMIFS($F$4:$F$803 , $D$4:$D$803, "Ăn uống", $E$4:$E$803, "chồng") | K3: =SUMIFS($F$4:$F$803 , $D$4:$D$803, "vui chơi", $E$4:$E$803, "chồng") | L3: =SUMIFS($F$4:$F$803 , $D$4:$D$803, "Công việc", $E$4:$E$803, "chồng") | M3: =SUMIFS($F$4:$F$803 , $D$4:$D$803, "học tập", $E$4:$E$803, "chồng") | N3: =SUMIFS($F$4:$F$803 , $D$4:$D$803, "đồ dùng GĐ", $E$4:$E$803, "chồng") | O3: =SUMIFS($F$4:$F$803 , $D$4:$D$803, "phí tiện ích", $E$4:$E$803, "chồng") | P3: =SUMIFS($F$4:$F$803 , $D$4:$D$803, "Làm đẹp", $E$4:$E$803, "chồng") | Q3: =SUMIFS($F$4:$F$803 , $D$4:$D$803, "Y tế", $E$4:$E$803, "chồng") | R3: =SUMIFS($F$4:$F$803 , $D$4:$D$803, "event", $E$4:$E$803, "chồng") | S3: =SUMIFS($F$4:$F$803 , $D$4:$D$803, "Nợ", $E$4:$E$803, "chồng")
C4: nợ ck shinhan | D4: Nợ | E4: chồng | F4: 4500000 | H4: vợ | I4: =SUM(J4:S4) | J4: =SUMIFS($F$4:$F$803 , $D$4:$D$803, "Ăn uống", $E$4:$E$803, "vợ") | K4: =SUMIFS($F$4:$F$803 , $D$4:$D$803, "vui chơi", $E$4:$E$803, "vợ") | L4: =SUMIFS($F$4:$F$803 , $D$4:$D$803, "Công việc", $E$4:$E$803, "vợ") | M4: =SUMIFS($F$4:$F$803 , $D$4:$D$803, "học tập", $E$4:$E$803, "vợ") | N4: =SUMIFS($F$4:$F$803 , $D$4:$D$803, "đồ dùng GĐ", $E$4:$E$803, "vợ") | O4: =SUMIFS($F$4:$F$803 , $D$4:$D$803, "phí tiện ích", $E$4:$E$803, "vợ") | P4: =SUMIFS($F$4:$F$803 , $D$4:$D$803, "Làm đẹp", $E$4:$E$803, "vợ") | Q4: =SUMIFS($F$4:$F$803 , $D$4:$D$803, "Y tế", $E$4:$E$803, "vợ") | R4: =SUMIFS($F$4:$F$803 , $D$4:$D$803, "event", $E$4:$E$803, "vợ") | S4: =SUMIFS($F$4:$F$803 , $D$4:$D$803, "Nợ", $E$4:$E$803, "vợ")
C5: nợ thuế ck | D5: Nợ | E5: chồng | F5: 3000000 | H5: subo | I5: =SUM(J5:S5) | J5: =SUMIFS($F$4:$F$803 , $D$4:$D$803, "Ăn uống", $E$4:$E$803, "SUBO") | K5: =SUMIFS($F$4:$F$803 , $D$4:$D$803, "vui chơi", $E$4:$E$803, "SUBO") | L5: =SUMIFS($F$4:$F$803 , $D$4:$D$803, "Công việc", $E$4:$E$803, "SUBO") | M5: =SUMIFS($F$4:$F$803 , $D$4:$D$803, "học tập", $E$4:$E$803, "SUBO") | N5: =SUMIFS($F$4:$F$803 , $D$4:$D$803, "đồ dùng GĐ", $E$4:$E$803, "SUBO") | O5: =SUMIFS($F$4:$F$803 , $D$4:$D$803, "phí tiện ích", $E$4:$E$803, "SUBO") | P5: =SUMIFS($F$4:$F$803 , $D$4:$D$803, "Làm đẹp", $E$4:$E$803, "SUBO") | Q5: =SUMIFS($F$4:$F$803 , $D$4:$D$803, "Y tế", $E$4:$E$803, "SUBO") | R5: =SUMIFS($F$4:$F$803 , $D$4:$D$803, "event", $E$4:$E$803, "SUBO") | S5: =SUMIFS($F$4:$F$803 , $D$4:$D$803, "Nợ", $E$4:$E$803, "SUBO")
C6: nợ đt vk | D6: Nợ | E6: vợ | F6: 3000000 | H6: sugi | I6: =SUM(J6:S6) | J6: =SUMIFS($F$4:$F$803 , $D$4:$D$803, "Ăn uống", $E$4:$E$803, "SUGI") | K6: =SUMIFS($F$4:$F$803 , $D$4:$D$803, "vui chơi", $E$4:$E$803, "SUGI") | L6: =SUMIFS($F$4:$F$803 , $D$4:$D$803, "Công việc", $E$4:$E$803, "SUGI") | M6: =SUMIFS($F$4:$F$803 , $D$4:$D$803, "học tập", $E$4:$E$803, "SUGI") | N6: =SUMIFS($F$4:$F$803 , $D$4:$D$803, "đồ dùng GĐ", $E$4:$E$803, "SUGI") | O6: =SUMIFS($F$4:$F$803 , $D$4:$D$803, "phí tiện ích", $E$4:$E$803, "SUGI") | P6: =SUMIFS($F$4:$F$803 , $D$4:$D$803, "Làm đẹp", $E$4:$E$803, "SUGI") | Q6: =SUMIFS($F$4:$F$803 , $D$4:$D$803, "Y tế", $E$4:$E$803, "SUGI") | R6: =SUMIFS($F$4:$F$803 , $D$4:$D$803, "event", $E$4:$E$803, "SUGI") | S6: =SUMIFS($F$4:$F$803 , $D$4:$D$803, "Nợ", $E$4:$E$803, "SUGI")
C7: học phí subo | D7: học tập | E7: SUBO | F7: =9350000+1720000+300000 | I7: sum | J7: =SUM(J2:J6) | K7: =SUM(K2:K6) | L7: =SUM(L2:L6) | M7: =SUM(M2:M6) | N7: =SUM(N2:N6) | O7: =SUM(O2:O6) | P7: =SUM(P2:P6) | Q7: =SUM(Q2:Q6) | ... S7: =SUM(S2:S6)
C8: thẻ xe cc | D8: phí tiện ích | E8: Chung | F8: 1020000 | I8: % | J8: =J7/$I$1 | K8: =K7/$I$1 | L8: =L7/$I$1 | M8: =M7/$I$1 | N8: =N7/$I$1 | O8: =O7/$I$1 | P8: =P7/$I$1 | Q8: =Q7/$I$1 | ... S8: =S7/$I$1
C9: bánh mì | D9: Ăn uống | E9: Chung | F9: 115000
C10: bhx | D10: Ăn uống | E10: Chung | F10: 140000
C11: aeon | D11: Ăn uống | E11: Chung | F11: 749000 | V11: =J4/14
C12: chat gpt | D12: phí tiện ích | E12: Chung | F12: =582000+11000
C13: tiền điện | D13: phí tiện ích | E13: Chung | F13: =1889000 | V13: =J3/14
C14: tiền mạng | D14: phí tiện ích | E14: Chung | F14: 220000
C15: vé mb | D15: event | E15: vợ | F15: 1975000
C16: đồ chơi warehouse sale | D16: vui chơi | E16: SUBO | F16: =1351000+298000+2473000+279000
C17: bhx | D17: Ăn uống | E17: Chung | F17: 154000
C18: thuốc tây | D18: Y tế | E18: Chung | F18: 98000
C19: coop | D19: Ăn uống | E19: Chung | F19: 50000
C20: xăng | D20: phí tiện ích | E20: chồng | F20: 70000
C21: bún đậu | D21: Ăn uống | E21: Chung | F21: =134000+231000
C22: coop, emart, win | D22: Ăn uống | E22: Chung | F22: =27000+1357000+55000
C23: bv nhi đồng | D23: Y tế | E23: SUGI | F23: =150000+610000
C24: vinamilk | D24: Ăn uống | E24: Chung | F24: 69000
C25: cá tai tượng | D25: Ăn uống | E25: Chung | F25: 200000
C26: tip massage | D26: Làm đẹp | E26: vợ | F26: 50000
C27: bồn cầu, vòi nước | D27: đồ dùng GĐ | E27: Chung | F27: =280000+380000
C28: bu san. | D28: Ăn uống | E28: Chung | F28: 200000
C29: đt vợ | D29: phí tiện ích | E29: vợ | F29: =95000+45000+50000
C30: đồ làm bânh | D30: Ăn uống | E30: Chung | F30: 100000
C31: đam mê nấu nướng | D31: học tập | E31: vợ | F31: 160000
C32: bv nhi đồng | D32: Y tế | E32: SUGI | F32: 325000
C33: phí qlcc | D33: phí tiện ích | E33: Chung | F33: 379000
C34: ăn uống | D34: Ăn uống | E34: Chung | F34: 155000
C35: bhx | D35: Ăn uống | E35: Chung | F35: 120000
C36: emart | D36: Ăn uống | E36: Chung | F36: =807000+80000
C37: coop | D37: Ăn uống | E37: Chung | F37: 105000
C38: coop | D38: Ăn uống
C39: xăng vk | D39: phí tiện ích | E39: vợ | F39: 90000
C40: coop | D40: Ăn uống | E40: Chung | F40: 442000
...

Sheet T9 - DETAIL
H1: Tổng | I1: =SUM(F4:F1015) | J1: ăn uống | K1: vui chơi | L1: công việc | M1: học tập | N1: đồ dùng GĐ | O1: Phí tiện ích | P1: làm đẹp | Q1: y tế | R1: event | S1: nợ
B2: Ngày | C2: nội dung | D2: Hạng mục | E2: Phân loại | F2: Số Tiền | H2: Chung | I2: =SUM(J2:S2) | J2: =SUMIFS($F$4:$F$834 , $D$4:$D$834, "Ăn uống", $E$4:$E$834, "chung") | K2: =SUMIFS($F$4:$F$834 , $D$4:$D$834, "vui chơi", $E$4:$E$834, "chung") | L2: =SUMIFS($F$4:$F$834 , $D$4:$D$834, "Công việc", $E$4:$E$834, "chung") | M2: =SUMIFS($F$4:$F$834 , $D$4:$D$834, "học tập", $E$4:$E$834, "chung") | N2: =SUMIFS($F$4:$F$834 , $D$4:$D$834, "đồ dùng GĐ", $E$4:$E$834, "chung") | O2: =SUMIFS($F$4:$F$834 , $D$4:$D$834, "phí tiện ích", $E$4:$E$834, "chung") | P2: =SUMIFS($F$4:$F$834 , $D$4:$D$834, "Làm đẹp", $E$4:$E$834, "chung") | Q2: =SUMIFS($F$4:$F$834 , $D$4:$D$834, "Y tế", $E$4:$E$834, "chung") | R2: =SUMIFS($F$4:$F$834 , $D$4:$D$834, "event", $E$4:$E$834, "chung") | S2: =SUMIFS($F$4:$F$834 , $D$4:$D$834, "Nợ", $E$4:$E$834, "chung")
F3: =SUM(F4:F834) | H3: Chồng | I3: =SUM(J3:S3) | J3: =SUMIFS($F$4:$F$834 , $D$4:$D$834, "Ăn uống", $E$4:$E$834, "chồng") | K3: =SUMIFS($F$4:$F$834 , $D$4:$D$834, "vui chơi", $E$4:$E$834, "chồng") | L3: =SUMIFS($F$4:$F$834 , $D$4:$D$834, "Công việc", $E$4:$E$834, "chồng") | M3: =SUMIFS($F$4:$F$834 , $D$4:$D$834, "học tập", $E$4:$E$834, "chồng") | N3: =SUMIFS($F$4:$F$834 , $D$4:$D$834, "đồ dùng GĐ", $E$4:$E$834, "chồng") | O3: =SUMIFS($F$4:$F$834 , $D$4:$D$834, "phí tiện ích", $E$4:$E$834, "chồng") | P3: =SUMIFS($F$4:$F$834 , $D$4:$D$834, "Làm đẹp", $E$4:$E$834, "chồng") | Q3: =SUMIFS($F$4:$F$834 , $D$4:$D$834, "Y tế", $E$4:$E$834, "chồng") | R3: =SUMIFS($F$4:$F$834 , $D$4:$D$834, "event", $E$4:$E$834, "chồng") | S3: =SUMIFS($F$4:$F$834 , $D$4:$D$834, "Nợ", $E$4:$E$834, "chồng")
C4: nợ ck shinhan | D4: Nợ | E4: chồng | F4: 4500000 | H4: vợ | I4: =SUM(J4:S4) | J4: =SUMIFS($F$4:$F$834 , $D$4:$D$834, "Ăn uống", $E$4:$E$834, "vợ") | K4: =SUMIFS($F$4:$F$834 , $D$4:$D$834, "vui chơi", $E$4:$E$834, "vợ") | L4: =SUMIFS($F$4:$F$834 , $D$4:$D$834, "Công việc", $E$4:$E$834, "vợ") | M4: =SUMIFS($F$4:$F$834 , $D$4:$D$834, "học tập", $E$4:$E$834, "vợ") | N4: =SUMIFS($F$4:$F$834 , $D$4:$D$834, "đồ dùng GĐ", $E$4:$E$834, "vợ") | O4: =SUMIFS($F$4:$F$834 , $D$4:$D$834, "phí tiện ích", $E$4:$E$834, "vợ") | P4: =SUMIFS($F$4:$F$834 , $D$4:$D$834, "Làm đẹp", $E$4:$E$834, "vợ") | Q4: =SUMIFS($F$4:$F$834 , $D$4:$D$834, "Y tế", $E$4:$E$834, "vợ") | R4: =SUMIFS($F$4:$F$834 , $D$4:$D$834, "event", $E$4:$E$834, "vợ") | S4: =SUMIFS($F$4:$F$834 , $D$4:$D$834, "Nợ", $E$4:$E$834, "vợ")
C5: nợ thuế ck | D5: Nợ | E5: chồng | F5: 3000000 | H5: subo | I5: =SUM(J5:S5) | J5: =SUMIFS($F$4:$F$834 , $D$4:$D$834, "Ăn uống", $E$4:$E$834, "SUBO") | K5: =SUMIFS($F$4:$F$834 , $D$4:$D$834, "vui chơi", $E$4:$E$834, "SUBO") | L5: =SUMIFS($F$4:$F$834 , $D$4:$D$834, "Công việc", $E$4:$E$834, "SUBO") | M5: =SUMIFS($F$4:$F$834 , $D$4:$D$834, "học tập", $E$4:$E$834, "SUBO") | N5: =SUMIFS($F$4:$F$834 , $D$4:$D$834, "đồ dùng GĐ", $E$4:$E$834, "SUBO") | O5: =SUMIFS($F$4:$F$834 , $D$4:$D$834, "phí tiện ích", $E$4:$E$834, "SUBO") | P5: =SUMIFS($F$4:$F$834 , $D$4:$D$834, "Làm đẹp", $E$4:$E$834, "SUBO") | Q5: =SUMIFS($F$4:$F$834 , $D$4:$D$834, "Y tế", $E$4:$E$834, "SUBO") | R5: =SUMIFS($F$4:$F$834 , $D$4:$D$834, "event", $E$4:$E$834, "SUBO") | S5: =SUMIFS($F$4:$F$834 , $D$4:$D$834, "Nợ", $E$4:$E$834, "SUBO")
C6: nợ đt vk | D6: Nợ | E6: vợ | F6: 3000000 | H6: sugi | I6: =SUM(J6:S6) | J6: =SUMIFS($F$4:$F$834 , $D$4:$D$834, "Ăn uống", $E$4:$E$834, "SUGI") | K6: =SUMIFS($F$4:$F$834 , $D$4:$D$834, "vui chơi", $E$4:$E$834, "SUGI") | L6: =SUMIFS($F$4:$F$834 , $D$4:$D$834, "Công việc", $E$4:$E$834, "SUGI") | M6: =SUMIFS($F$4:$F$834 , $D$4:$D$834, "học tập", $E$4:$E$834, "SUGI") | N6: =SUMIFS($F$4:$F$834 , $D$4:$D$834, "đồ dùng GĐ", $E$4:$E$834, "SUGI") | O6: =SUMIFS($F$4:$F$834 , $D$4:$D$834, "phí tiện ích", $E$4:$E$834, "SUGI") | P6: =SUMIFS($F$4:$F$834 , $D$4:$D$834, "Làm đẹp", $E$4:$E$834, "SUGI") | Q6: =SUMIFS($F$4:$F$834 , $D$4:$D$834, "Y tế", $E$4:$E$834, "SUGI") | R6: =SUMIFS($F$4:$F$834 , $D$4:$D$834, "event", $E$4:$E$834, "SUGI") | S6: =SUMIFS($F$4:$F$834 , $D$4:$D$834, "Nợ", $E$4:$E$834, "SUGI")
C7: học phí subo | D7: học tập | E7: SUBO | F7: =38420000/4+3000000+2420000+300000 | I7: sum | J7: =SUM(J2:J6) | K7: =SUM(K2:K6) | L7: =SUM(L2:L6) | M7: =SUM(M2:M6) | N7: =SUM(N2:N6) | O7: =SUM(O2:O6) | P7: =SUM(P2:P6) | Q7: =SUM(Q2:Q6) | ... S7: =SUM(S2:S6)
C8: chơi khu vui chơi | D8: vui chơi | E8: SUBO | F8: 160000 | I8: % | J8: =J7/$I$1 | K8: =K7/$I$1 | L8: =L7/$I$1 | M8: =M7/$I$1 | N8: =N7/$I$1 | O8: =O7/$I$1 | P8: =P7/$I$1 | Q8: =Q7/$I$1 | ... S8: =S7/$I$1
C9: vs máy lạnh | D9: phí tiện ích | E9: Chung | F9: 210000
C10: ministop | D10: Ăn uống | E10: Chung | F10: 57000
C11: phở gà, tàu hũ | D11: Ăn uống | E11: Chung | F11: 125000 | V11: =J4/14
C12: sửa xe | D12: phí tiện ích | E12: chồng | F12: =2200000+10400000
C13: be | D13: phí tiện ích | E13: Chung | F13: 200000 | V13: =J3/14
C14: emart | D14: Ăn uống | E14: Chung | F14: =1727000
C15: phong cua | D15: Ăn uống | E15: Chung | F15: 628000
C16: xăng | D16: phí tiện ích | E16: vợ | F16: =86000*2
C17: gà texas | D17: Ăn uống | E17: Chung | F17: 248000
C18: trà sữa,nem nướng | D18: Ăn uống | E18: Chung | F18: =162000+679000
C19: bánh rán | D19: Ăn uống | E19: Chung | F19: 75000
C20: phở lệ | D20: Ăn uống | E20: Chung | F20: 233000
C21: sầu riêng | D21: Ăn uống | E21: Chung | F21: 300000
C22: ghẹ, hàu | D22: Ăn uống | E22: Chung | F22: 1140000
C23: măng cụt. | D23: Ăn uống | E23: Chung | F23: 160000
C24: giấy dán tường | D24: đồ dùng GĐ | E24: Chung | F24: 120000
C25: dưa hấu, thơm | D25: Ăn uống | E25: Chung | F25: 68000
C26: quần áo | D26: Làm đẹp | E26: SUGI | F26: =310000+265000
C27: phí qlcc | D27: phí tiện ích | E27: Chung | F27: 296000
C28: quần chip | D28: đồ dùng GĐ | E28: vợ | F28: 735000
C29: sushi emart | D29: Ăn uống | E29: Chung | F29: 50000
C30: cơm tấm shopee | D30: Ăn uống | E30: Chung | F30: 738000
C31: bánh mì chim chạy | D31: Ăn uống | E31: Chung | F31: 200000
C32: đàn | D32: học tập | E32: SUBO | F32: 7500000
C33: winmart | D33: Ăn uống | E33: Chung | F33: 42000
C34: kingfood | D34: Ăn uống | E34: Chung | F34: 177000
C35: hachi | D35: đồ dùng GĐ | E35: Chung | F35: 456000
C36: emart | D36: Ăn uống | E36: Chung | F36: =1958000+1070000+17000
C37: điên | D37: phí tiện ích | E37: Chung | F37: 2076000
C38: internet | D38: phí tiện ích | E38: Chung | F38: 220000
C39: chat gpt | D39: Công việc | E39: Chung | F39: =32220000-31635000
C40: chaả cá | D40: Ăn uống | E40: Chung | F40: 160000
...

Sheet T10 - DETAIL
H1: Tổng | I1: =SUM(F4:F1016) | J1: ăn uống | K1: vui chơi | L1: công việc | M1: học tập | N1: đồ dùng GĐ | O1: Phí tiện ích | P1: làm đẹp | Q1: y tế | R1: event | S1: nợ
B2: Ngày | C2: nội dung | D2: Hạng mục | E2: Phân loại | F2: Số Tiền | H2: Chung | I2: =SUM(J2:S2) | J2: =SUMIFS($F$4:$F$835 , $D$4:$D$835, "Ăn uống", $E$4:$E$835, "chung") | K2: =SUMIFS($F$4:$F$835 , $D$4:$D$835, "vui chơi", $E$4:$E$835, "chung") | L2: =SUMIFS($F$4:$F$835 , $D$4:$D$835, "Công việc", $E$4:$E$835, "chung") | M2: =SUMIFS($F$4:$F$835 , $D$4:$D$835, "học tập", $E$4:$E$835, "chung") | N2: =SUMIFS($F$4:$F$835 , $D$4:$D$835, "đồ dùng GĐ", $E$4:$E$835, "chung") | O2: =SUMIFS($F$4:$F$835 , $D$4:$D$835, "phí tiện ích", $E$4:$E$835, "chung") | P2: =SUMIFS($F$4:$F$835 , $D$4:$D$835, "Làm đẹp", $E$4:$E$835, "chung") | Q2: =SUMIFS($F$4:$F$835 , $D$4:$D$835, "Y tế", $E$4:$E$835, "chung") | R2: =SUMIFS($F$4:$F$835 , $D$4:$D$835, "event", $E$4:$E$835, "chung") | S2: =SUMIFS($F$4:$F$835 , $D$4:$D$835, "Nợ", $E$4:$E$835, "chung")
F3: =SUM(F4:F835) | H3: Chồng | I3: =SUM(J3:S3) | J3: =SUMIFS($F$4:$F$835 , $D$4:$D$835, "Ăn uống", $E$4:$E$835, "chồng") | K3: =SUMIFS($F$4:$F$835 , $D$4:$D$835, "vui chơi", $E$4:$E$835, "chồng") | L3: =SUMIFS($F$4:$F$835 , $D$4:$D$835, "Công việc", $E$4:$E$835, "chồng") | M3: =SUMIFS($F$4:$F$835 , $D$4:$D$835, "học tập", $E$4:$E$835, "chồng") | N3: =SUMIFS($F$4:$F$835 , $D$4:$D$835, "đồ dùng GĐ", $E$4:$E$835, "chồng") | O3: =SUMIFS($F$4:$F$835 , $D$4:$D$835, "phí tiện ích", $E$4:$E$835, "chồng") | P3: =SUMIFS($F$4:$F$835 , $D$4:$D$835, "Làm đẹp", $E$4:$E$835, "chồng") | Q3: =SUMIFS($F$4:$F$835 , $D$4:$D$835, "Y tế", $E$4:$E$835, "chồng") | R3: =SUMIFS($F$4:$F$835 , $D$4:$D$835, "event", $E$4:$E$835, "chồng") | S3: =SUMIFS($F$4:$F$835 , $D$4:$D$835, "Nợ", $E$4:$E$835, "chồng")
C4: hphi subo | D4: học tập | E4: SUBO | F4: =38420000/4 | H4: vợ | I4: =SUM(J4:S4) | J4: =SUMIFS($F$4:$F$835 , $D$4:$D$835, "Ăn uống", $E$4:$E$835, "vợ") | K4: =SUMIFS($F$4:$F$835 , $D$4:$D$835, "vui chơi", $E$4:$E$835, "vợ") | L4: =SUMIFS($F$4:$F$835 , $D$4:$D$835, "Công việc", $E$4:$E$835, "vợ") | M4: =SUMIFS($F$4:$F$835 , $D$4:$D$835, "học tập", $E$4:$E$835, "vợ") | N4: =SUMIFS($F$4:$F$835 , $D$4:$D$835, "đồ dùng GĐ", $E$4:$E$835, "vợ") | O4: =SUMIFS($F$4:$F$835 , $D$4:$D$835, "phí tiện ích", $E$4:$E$835, "vợ") | P4: =SUMIFS($F$4:$F$835 , $D$4:$D$835, "Làm đẹp", $E$4:$E$835, "vợ") | Q4: =SUMIFS($F$4:$F$835 , $D$4:$D$835, "Y tế", $E$4:$E$835, "vợ") | R4: =SUMIFS($F$4:$F$835 , $D$4:$D$835, "event", $E$4:$E$835, "vợ") | S4: =SUMIFS($F$4:$F$835 , $D$4:$D$835, "Nợ", $E$4:$E$835, "vợ")
C5: thuế ck | D5: Nợ | E5: chồng | F5: 3000000 | H5: subo | I5: =SUM(J5:S5) | J5: =SUMIFS($F$4:$F$835 , $D$4:$D$835, "Ăn uống", $E$4:$E$835, "SUBO") | K5: =SUMIFS($F$4:$F$835 , $D$4:$D$835, "vui chơi", $E$4:$E$835, "SUBO") | L5: =SUMIFS($F$4:$F$835 , $D$4:$D$835, "Công việc", $E$4:$E$835, "SUBO") | M5: =SUMIFS($F$4:$F$835 , $D$4:$D$835, "học tập", $E$4:$E$835, "SUBO") | N5: =SUMIFS($F$4:$F$835 , $D$4:$D$835, "đồ dùng GĐ", $E$4:$E$835, "SUBO") | O5: =SUMIFS($F$4:$F$835 , $D$4:$D$835, "phí tiện ích", $E$4:$E$835, "SUBO") | P5: =SUMIFS($F$4:$F$835 , $D$4:$D$835, "Làm đẹp", $E$4:$E$835, "SUBO") | Q5: =SUMIFS($F$4:$F$835 , $D$4:$D$835, "Y tế", $E$4:$E$835, "SUBO") | R5: =SUMIFS($F$4:$F$835 , $D$4:$D$835, "event", $E$4:$E$835, "SUBO") | S5: =SUMIFS($F$4:$F$835 , $D$4:$D$835, "Nợ", $E$4:$E$835, "SUBO")
C6: shin han | D6: Nợ | E6: chồng | F6: 4500000
C7: đt vk | D7: Nợ | E7: vợ | F7: 2490000 | H7: sugi | I7: =SUM(J7:S7) | J7: =SUMIFS($F$4:$F$835 , $D$4:$D$835, "Ăn uống", $E$4:$E$835, "SUGI") | K7: =SUMIFS($F$4:$F$835 , $D$4:$D$835, "vui chơi", $E$4:$E$835, "SUGI") | L7: =SUMIFS($F$4:$F$835 , $D$4:$D$835, "Công việc", $E$4:$E$835, "SUGI") | M7: =SUMIFS($F$4:$F$835 , $D$4:$D$835, "học tập", $E$4:$E$835, "SUGI") | N7: =SUMIFS($F$4:$F$835 , $D$4:$D$835, "đồ dùng GĐ", $E$4:$E$835, "SUGI") | O7: =SUMIFS($F$4:$F$835 , $D$4:$D$835, "phí tiện ích", $E$4:$E$835, "SUGI") | P7: =SUMIFS($F$4:$F$835 , $D$4:$D$835, "Làm đẹp", $E$4:$E$835, "SUGI") | Q7: =SUMIFS($F$4:$F$835 , $D$4:$D$835, "Y tế", $E$4:$E$835, "SUGI") | R7: =SUMIFS($F$4:$F$835 , $D$4:$D$835, "event", $E$4:$E$835, "SUGI") | S7: =SUMIFS($F$4:$F$835 , $D$4:$D$835, "Nợ", $E$4:$E$835, "SUGI")
C8: cá | D8: Ăn uống | E8: Chung | F8: 120000 | I8: sum | J8: =SUM(J2:J7) | K8: =SUM(K2:K7) | L8: =SUM(L2:L7) | M8: =SUM(M2:M7) | N8: =SUM(N2:N7) | O8: =SUM(O2:O7) | P8: =SUM(P2:P7) | Q8: =SUM(Q2:Q7) | ... S8: =SUM(S2:S7)
C9: qao vk | D9: Làm đẹp | E9: vợ | F9: 710000 | I9: % | J9: =IFERROR(J8/$I$1, 0) | K9: =IFERROR(K8/$I$1, 0) | L9: =IFERROR(L8/$I$1, 0) | M9: =IFERROR(M8/$I$1, 0) | N9: =IFERROR(N8/$I$1, 0) | O9: =IFERROR(O8/$I$1, 0) | P9: =IFERROR(P8/$I$1, 0) | Q9: =IFERROR(Q8/$I$1, 0) | ... S9: =IFERROR(S8/$I$1, 0)
C10: chanh muối | D10: Ăn uống | E10: Chung | F10: 85000
C11: trứng, trứng muối | D11: Ăn uống | E11: Chung | F11: 137000
C12: coop văn thánh | D12: Ăn uống | E12: Chung | F12: =42000+101000 | G12: uob | V12: =J4/14
C13: phở võ quốc | D13: Ăn uống | E13: Chung | F13: 350000 | G13: uob
C14: coop rạch miễu | D14: Ăn uống | E14: Chung | F14: 1440000 | G14: uob | V14: =J3/14
C15: coop phan văn hân | D15: Ăn uống | E15: Chung | F15: 90000 | G15: uob
C16: thuốc tây | D16: Y tế | E16: Chung | F16: =165000+149000 | G16: uob
C17: khay sấy | D17: đồ dùng GĐ | E17: Chung | F17: 164000 | G17: vp sp
C18: củ đậu, bánh mì | D18: Ăn uống | E18: Chung | F18: =9000+12000
C19: đền cty | D19: Công việc | E19: chồng
C20: be đi e mart | D20: phí tiện ích | E20: Chung | F20: 103000 | G20: vp
C21: emart | D21: Ăn uống | E21: Chung | F21: =202000+2091000 | G21: uob
C22: nạp game | D22: vui chơi | E22: Chung | F22: 400000 | G22: uob
C23: nước giặt | D23: đồ dùng GĐ | E23: Chung | F23: 127000 | G23: vp sp
C24: khay nướng | D24: đồ dùng GĐ | E24: Chung | F24: 162000 | G24: vp sp
C25: bao rác | D25: đồ dùng GĐ | E25: Chung | F25: 55000 | G25: vpsp
C26: kem đr | D26: đồ dùng GĐ | E26: Chung | F26: 86000 | G26: vp sp
C27: bột xá xíu | D27: Ăn uống | E27: Chung | F27: 37000 | G27: vp sp
C28: coop | D28: Ăn uống | E28: Chung | F28: 40000 | G28: vp sp
C29: finish | D29: đồ dùng GĐ | E29: Chung | F29: 671000 | G29: vp sp
C30: kem bôi hăm | D30: đồ dùng GĐ | E30: SUGI | F30: 132000 | G30: vp sp
C31: nc hồ cá | D31: đồ dùng GĐ | E31: Chung | F31: 126000 | G31: vp sp
C32: đồ lót | D32: Làm đẹp | E32: Chung | F32: 606000 | G32: vp sp
C33: ăn chè | D33: vui chơi | E33: Chung | F33: 113000 | G33: vp sp
... C37: tô tượng | D37: vui chơi | E37: SUBO | F37: 60000 | G37: uob
C38: share áo mr park | D38: event | E38: vợ | F38: 100000
C39: phí qlcc | D39: phí tiện ích | E39: Chung | F39: 388000
C40: cá, đồ ăn | D40: Ăn uống | E40: Chung | F40: 560000
C41: đồ abby | D41: Ăn uống | E41: Chung | F41: 213000
C42: đi chợ sáng | D42: Ăn uống | E42: Chung | F42: =25000+10000+18000+20000+24000+80000
C43: bỉm con cung | D43: đồ dùng GĐ | E43: SUGI | F43: 378000 | G43: vp
...

Sheet T11 - DETAIL
H1: Tổng | I1: =SUM(F4:F1015) | J1: ăn uống | K1: vui chơi | L1: công việc | M1: học tập | N1: đồ dùng GĐ | O1: Phí tiện ích | P1: làm đẹp | Q1: y tế | R1: event | S1: nợ
B2: Ngày | C2: nội dung | D2: Hạng mục | E2: Phân loại | F2: Số Tiền | H2: Chung | I2: =SUM(J2:S2) | J2: =SUMIFS($F$4:$F$834 , $D$4:$D$834, "Ăn uống", $E$4:$E$834, "chung") | K2: =SUMIFS($F$4:$F$834 , $D$4:$D$834, "vui chơi", $E$4:$E$834, "chung") | L2: =SUMIFS($F$4:$F$834 , $D$4:$D$834, "Công việc", $E$4:$E$834, "chung") | M2: =SUMIFS($F$4:$F$834 , $D$4:$D$834, "học tập", $E$4:$E$834, "chung") | N2: =SUMIFS($F$4:$F$834 , $D$4:$D$834, "đồ dùng GĐ", $E$4:$E$834, "chung") | O2: =SUMIFS($F$4:$F$834 , $D$4:$D$834, "phí tiện ích", $E$4:$E$834, "chung") | P2: =SUMIFS($F$4:$F$834 , $D$4:$D$834, "Làm đẹp", $E$4:$E$834, "chung") | Q2: =SUMIFS($F$4:$F$834 , $D$4:$D$834, "Y tế", $E$4:$E$834, "chung") | R2: =SUMIFS($F$4:$F$834 , $D$4:$D$834, "event", $E$4:$E$834, "chung") | S2: =SUMIFS($F$4:$F$834 , $D$4:$D$834, "Nợ", $E$4:$E$834, "chung")
F3: =SUM(F4:F834) | H3: Chồng | I3: =SUM(J3:S3) | J3: =SUMIFS($F$4:$F$834 , $D$4:$D$834, "Ăn uống", $E$4:$E$834, "chồng") | K3: =SUMIFS($F$4:$F$834 , $D$4:$D$834, "vui chơi", $E$4:$E$834, "chồng") | L3: =SUMIFS($F$4:$F$834 , $D$4:$D$834, "Công việc", $E$4:$E$834, "chồng") | M3: =SUMIFS($F$4:$F$834 , $D$4:$D$834, "học tập", $E$4:$E$834, "chồng") | N3: =SUMIFS($F$4:$F$834 , $D$4:$D$834, "đồ dùng GĐ", $E$4:$E$834, "chồng") | O3: =SUMIFS($F$4:$F$834 , $D$4:$D$834, "phí tiện ích", $E$4:$E$834, "chồng") | P3: =SUMIFS($F$4:$F$834 , $D$4:$D$834, "Làm đẹp", $E$4:$E$834, "chồng") | Q3: =SUMIFS($F$4:$F$834 , $D$4:$D$834, "Y tế", $E$4:$E$834, "chồng") | R3: =SUMIFS($F$4:$F$834 , $D$4:$D$834, "event", $E$4:$E$834, "chồng") | S3: =SUMIFS($F$4:$F$834 , $D$4:$D$834, "Nợ", $E$4:$E$834, "chồng")
H4: vợ | I4: =SUM(J4:S4) | J4: =SUMIFS($F$4:$F$834 , $D$4:$D$834, "Ăn uống", $E$4:$E$834, "vợ") | K4: =SUMIFS($F$4:$F$834 , $D$4:$D$834, "vui chơi", $E$4:$E$834, "vợ") | L4: =SUMIFS($F$4:$F$834 , $D$4:$D$834, "Công việc", $E$4:$E$834, "vợ") | M4: =SUMIFS($F$4:$F$834 , $D$4:$D$834, "học tập", $E$4:$E$834, "vợ") | N4: =SUMIFS($F$4:$F$834 , $D$4:$D$834, "đồ dùng GĐ", $E$4:$E$834, "vợ") | O4: =SUMIFS($F$4:$F$834 , $D$4:$D$834, "phí tiện ích", $E$4:$E$834, "vợ") | P4: =SUMIFS($F$4:$F$834 , $D$4:$D$834, "Làm đẹp", $E$4:$E$834, "vợ") | Q4: =SUMIFS($F$4:$F$834 , $D$4:$D$834, "Y tế", $E$4:$E$834, "vợ") | R4: =SUMIFS($F$4:$F$834 , $D$4:$D$834, "event", $E$4:$E$834, "vợ") | S4: =SUMIFS($F$4:$F$834 , $D$4:$D$834, "Nợ", $E$4:$E$834, "vợ")
H5: subo | I5: =SUM(J5:S5) | J5: =SUMIFS($F$4:$F$834 , $D$4:$D$834, "Ăn uống", $E$4:$E$834, "SUBO") | K5: =SUMIFS($F$4:$F$834 , $D$4:$D$834, "vui chơi", $E$4:$E$834, "SUBO") | L5: =SUMIFS($F$4:$F$834 , $D$4:$D$834, "Công việc", $E$4:$E$834, "SUBO") | M5: =SUMIFS($F$4:$F$834 , $D$4:$D$834, "học tập", $E$4:$E$834, "SUBO") | N5: =SUMIFS($F$4:$F$834 , $D$4:$D$834, "đồ dùng GĐ", $E$4:$E$834, "SUBO") | O5: =SUMIFS($F$4:$F$834 , $D$4:$D$834, "phí tiện ích", $E$4:$E$834, "SUBO") | P5: =SUMIFS($F$4:$F$834 , $D$4:$D$834, "Làm đẹp", $E$4:$E$834, "SUBO") | Q5: =SUMIFS($F$4:$F$834 , $D$4:$D$834, "Y tế", $E$4:$E$834, "SUBO") | R5: =SUMIFS($F$4:$F$834 , $D$4:$D$834, "event", $E$4:$E$834, "SUBO") | S5: =SUMIFS($F$4:$F$834 , $D$4:$D$834, "Nợ", $E$4:$E$834, "SUBO")
H6: sugi | I6: =SUM(J6:S6) | J6: =SUMIFS($F$4:$F$834 , $D$4:$D$834, "Ăn uống", $E$4:$E$834, "SUGI") | K6: =SUMIFS($F$4:$F$834 , $D$4:$D$834, "vui chơi", $E$4:$E$834, "SUGI") | L6: =SUMIFS($F$4:$F$834 , $D$4:$D$834, "Công việc", $E$4:$E$834, "SUGI") | M6: =SUMIFS($F$4:$F$834 , $D$4:$D$834, "học tập", $E$4:$E$834, "SUGI") | N6: =SUMIFS($F$4:$F$834 , $D$4:$D$834, "đồ dùng GĐ", $E$4:$E$834, "SUGI") | O6: =SUMIFS($F$4:$F$834 , $D$4:$D$834, "phí tiện ích", $E$4:$E$834, "SUGI") | P6: =SUMIFS($F$4:$F$834 , $D$4:$D$834, "Làm đẹp", $E$4:$E$834, "SUGI") | Q6: =SUMIFS($F$4:$F$834 , $D$4:$D$834, "Y tế", $E$4:$E$834, "SUGI") | R6: =SUMIFS($F$4:$F$834 , $D$4:$D$834, "event", $E$4:$E$834, "SUGI") | S6: =SUMIFS($F$4:$F$834 , $D$4:$D$834, "Nợ", $E$4:$E$834, "SUGI")
I7: sum | J7: =SUM(J2:J6) | K7: =SUM(K2:K6) | L7: =SUM(L2:L6) | M7: =SUM(M2:M6) | N7: =SUM(N2:N6) | O7: =SUM(O2:O6) | P7: =SUM(P2:P6) | Q7: =SUM(Q2:Q6) | ... S7: =SUM(S2:S6)
I8: % | J8: =IFERROR(J7/$I$1, 0) | K8: =IFERROR(K7/$I$1, 0) | L8: =IFERROR(L7/$I$1, 0) | M8: =IFERROR(M7/$I$1, 0) | N8: =IFERROR(N7/$I$1, 0) | O8: =IFERROR(O7/$I$1, 0) | P8: =IFERROR(P7/$I$1, 0) | Q8: =IFERROR(Q7/$I$1, 0) | ... S8: =IFERROR(S7/$I$1, 0)
V11: =J4/14
V13: =J3/14
T48: =J2+J3+J4
T50: =T48/20

Sheet T12 - DETAIL
H1: Tổng | I1: =SUM(F4:F1015) | J1: ăn uống | K1: vui chơi | L1: công việc | M1: học tập | N1: đồ dùng GĐ | O1: Phí tiện ích | P1: làm đẹp | Q1: y tế | R1: event | S1: nợ
B2: Ngày | C2: nội dung | D2: Hạng mục | E2: Phân loại | F2: Số Tiền | H2: Chung | I2: =SUM(J2:S2) | J2: =SUMIFS($F$4:$F$834 , $D$4:$D$834, "Ăn uống", $E$4:$E$834, "chung") | K2: =SUMIFS($F$4:$F$834 , $D$4:$D$834, "vui chơi", $E$4:$E$834, "chung") | L2: =SUMIFS($F$4:$F$834 , $D$4:$D$834, "Công việc", $E$4:$E$834, "chung") | M2: =SUMIFS($F$4:$F$834 , $D$4:$D$834, "học tập", $E$4:$E$834, "chung") | N2: =SUMIFS($F$4:$F$834 , $D$4:$D$834, "đồ dùng GĐ", $E$4:$E$834, "chung") | O2: =SUMIFS($F$4:$F$834 , $D$4:$D$834, "phí tiện ích", $E$4:$E$834, "chung") | P2: =SUMIFS($F$4:$F$834 , $D$4:$D$834, "Làm đẹp", $E$4:$E$834, "chung") | Q2: =SUMIFS($F$4:$F$834 , $D$4:$D$834, "Y tế", $E$4:$E$834, "chung") | R2: =SUMIFS($F$4:$F$834 , $D$4:$D$834, "event", $E$4:$E$834, "chung") | S2: =SUMIFS($F$4:$F$834 , $D$4:$D$834, "Nợ", $E$4:$E$834, "chung")
F3: =SUM(F4:F834) | H3: Chồng | I3: =SUM(J3:S3) | J3: =SUMIFS($F$4:$F$834 , $D$4:$D$834, "Ăn uống", $E$4:$E$834, "chồng") | K3: =SUMIFS($F$4:$F$834 , $D$4:$D$834, "vui chơi", $E$4:$E$834, "chồng") | L3: =SUMIFS($F$4:$F$834 , $D$4:$D$834, "Công việc", $E$4:$E$834, "chồng") | M3: =SUMIFS($F$4:$F$834 , $D$4:$D$834, "học tập", $E$4:$E$834, "chồng") | N3: =SUMIFS($F$4:$F$834 , $D$4:$D$834, "đồ dùng GĐ", $E$4:$E$834, "chồng") | O3: =SUMIFS($F$4:$F$834 , $D$4:$D$834, "phí tiện ích", $E$4:$E$834, "chồng") | P3: =SUMIFS($F$4:$F$834 , $D$4:$D$834, "Làm đẹp", $E$4:$E$834, "chồng") | Q3: =SUMIFS($F$4:$F$834 , $D$4:$D$834, "Y tế", $E$4:$E$834, "chồng") | R3: =SUMIFS($F$4:$F$834 , $D$4:$D$834, "event", $E$4:$E$834, "chồng") | S3: =SUMIFS($F$4:$F$834 , $D$4:$D$834, "Nợ", $E$4:$E$834, "chồng")
H4: vợ | I4: =SUM(J4:S4) | J4: =SUMIFS($F$4:$F$834 , $D$4:$D$834, "Ăn uống", $E$4:$E$834, "vợ") | K4: =SUMIFS($F$4:$F$834 , $D$4:$D$834, "vui chơi", $E$4:$E$834, "vợ") | L4: =SUMIFS($F$4:$F$834 , $D$4:$D$834, "Công việc", $E$4:$E$834, "vợ") | M4: =SUMIFS($F$4:$F$834 , $D$4:$D$834, "học tập", $E$4:$E$834, "vợ") | N4: =SUMIFS($F$4:$F$834 , $D$4:$D$834, "đồ dùng GĐ", $E$4:$E$834, "vợ") | O4: =SUMIFS($F$4:$F$834 , $D$4:$D$834, "phí tiện ích", $E$4:$E$834, "vợ") | P4: =SUMIFS($F$4:$F$834 , $D$4:$D$834, "Làm đẹp", $E$4:$E$834, "vợ") | Q4: =SUMIFS($F$4:$F$834 , $D$4:$D$834, "Y tế", $E$4:$E$834, "vợ") | R4: =SUMIFS($F$4:$F$834 , $D$4:$D$834, "event", $E$4:$E$834, "vợ") | S4: =SUMIFS($F$4:$F$834 , $D$4:$D$834, "Nợ", $E$4:$E$834, "vợ")
H5: subo | I5: =SUM(J5:S5) | J5: =SUMIFS($F$4:$F$834 , $D$4:$D$834, "Ăn uống", $E$4:$E$834, "SUBO") | K5: =SUMIFS($F$4:$F$834 , $D$4:$D$834, "vui chơi", $E$4:$E$834, "SUBO") | L5: =SUMIFS($F$4:$F$834 , $D$4:$D$834, "Công việc", $E$4:$E$834, "SUBO") | M5: =SUMIFS($F$4:$F$834 , $D$4:$D$834, "học tập", $E$4:$E$834, "SUBO") | N5: =SUMIFS($F$4:$F$834 , $D$4:$D$834, "đồ dùng GĐ", $E$4:$E$834, "SUBO") | O5: =SUMIFS($F$4:$F$834 , $D$4:$D$834, "phí tiện ích", $E$4:$E$834, "SUBO") | P5: =SUMIFS($F$4:$F$834 , $D$4:$D$834, "Làm đẹp", $E$4:$E$834, "SUBO") | Q5: =SUMIFS($F$4:$F$834 , $D$4:$D$834, "Y tế", $E$4:$E$834, "SUBO") | R5: =SUMIFS($F$4:$F$834 , $D$4:$D$834, "event", $E$4:$E$834, "SUBO") | S5: =SUMIFS($F$4:$F$834 , $D$4:$D$834, "Nợ", $E$4:$E$834, "SUBO")
H6: sugi | I6: =SUM(J6:S6) | J6: =SUMIFS($F$4:$F$834 , $D$4:$D$834, "Ăn uống", $E$4:$E$834, "SUGI") | K6: =SUMIFS($F$4:$F$834 , $D$4:$D$834, "vui chơi", $E$4:$E$834, "SUGI") | L6: =SUMIFS($F$4:$F$834 , $D$4:$D$834, "Công việc", $E$4:$E$834, "SUGI") | M6: =SUMIFS($F$4:$F$834 , $D$4:$D$834, "học tập", $E$4:$E$834, "SUGI") | N6: =SUMIFS($F$4:$F$834 , $D$4:$D$834, "đồ dùng GĐ", $E$4:$E$834, "SUGI") | O6: =SUMIFS($F$4:$F$834 , $D$4:$D$834, "phí tiện ích", $E$4:$E$834, "SUGI") | P6: =SUMIFS($F$4:$F$834 , $D$4:$D$834, "Làm đẹp", $E$4:$E$834, "SUGI") | Q6: =SUMIFS($F$4:$F$834 , $D$4:$D$834, "Y tế", $E$4:$E$834, "SUGI") | R6: =SUMIFS($F$4:$F$834 , $D$4:$D$834, "event", $E$4:$E$834, "SUGI") | S6: =SUMIFS($F$4:$F$834 , $D$4:$D$834, "Nợ", $E$4:$E$834, "SUGI")
I7: sum | J7: =SUM(J2:J6) | K7: =SUM(K2:K6) | L7: =SUM(L2:L6) | M7: =SUM(M2:M6) | N7: =SUM(N2:N6) | O7: =SUM(O2:O6) | P7: =SUM(P2:P6) | Q7: =SUM(Q2:Q6) | ... S7: =SUM(S2:S6)
I8: % | J8: =IFERROR(J7/$I$1, 0) | K8: =IFERROR(K7/$I$1, 0) | L8: =IFERROR(L7/$I$1, 0) | M8: =IFERROR(M7/$I$1, 0) | N8: =IFERROR(N7/$I$1, 0) | O8: =IFERROR(O7/$I$1, 0) | P8: =IFERROR(P7/$I$1, 0) | Q8: =IFERROR(Q7/$I$1, 0) | ... S8: =IFERROR(S7/$I$1, 0)
V11: =J4/14
V13: =J3/14
T48: =J2+J3+J4
T50: =T48/20

Sheet T7 - MASTER
B1: 46023
A3: I | B3: THU NHẬP | C3: 1 | D3: =SUM(D4:D7)
A4: 1 | B4: ck | D4: =SUM(E4:H4) | E4: 45700000 | F4: 8000000 | G4: 0 | H4: 0
A5: 2 | B5: vk | D5: =SUM(E5:H5) | E5: 30000000 | F5: 0 | G5: 0 | H5: 0
A6: 3 | B6: Subo | D6: =SUM(E6:H6) | E6: 0 | F6: 0 | G6: 0 | H6: 0
A7: 4 | B7: Sugi | D7: =SUM(E7:H7) | E7: 0 | F7: 0 | G7: 0 | H7: 0
A8: II | B8: TIẾT KIỆM | C8: 0.3 | D8: =D3*C8 | I8: CÒN LẠI | K8: =D3-D11
B9: TK thực tế | I9: CP ĐÃ TRỪ NHƯNG CHƯA ĐÓNG | J9: HỌC PHÍ
A10: III | B10: CHI PHÍ | C10: 0.7 | D10: =D3*C10 | J10: ĐIỆN THOẠI
B11: CP Thực tế | D11: =SUM(D12,D16,D18) | K11: =SUM(K8:K10)
A12: 1 | B12: Chi phí chung gia đình | C12: =IFERROR(D12/D11, 0) | D12: =SUM(D13:D15)
A13: a | B13: Chi phí chung | C13: =IFERROR(D13/$D$10, 0) | D13: ='T7 - DETAIL'!I2
A14: b | B14: Chi phí riêng subo | C14: =IFERROR(D14/$D$10, 0) | D14: ='T7 - DETAIL'!I5
A15: c | B15: chi phí riêng sugi | C15: =IFERROR(D15/$D$10, 0) | D15: ='T7 - DETAIL'!I6
A16: 2 | B16: Chi phí riêng ck (30%) | C16: =IFERROR(D16/D11, 0) | D16: ='T7 - DETAIL'!I3
B17: =30%*D10
A18: 3 | B18: Chi phí riêng vk (30%) | C18: =IFERROR(D18/D11, 0) | D18: ='T7 - DETAIL'!I4
B19: =30%*D10

Sheet T7 - DETAIL
H1: Tổng | I1: =SUM(F4:F1015) | J1: ăn uống | K1: vui chơi | L1: công việc | M1: học tập | N1: đồ dùng GĐ | O1: Phí tiện ích | P1: làm đẹp | Q1: y tế | R1: event | S1: nợ
B2: Ngày | C2: nội dung | D2: Hạng mục | E2: Phân loại | F2: Số Tiền | H2: Chung | I2: =SUM(J2:S2) | J2: =SUMIFS($F$4:$F$834 , $D$4:$D$834, "Ăn uống", $E$4:$E$834, "chung") | K2: =SUMIFS($F$4:$F$834 , $D$4:$D$834, "vui chơi", $E$4:$E$834, "chung") | L2: =SUMIFS($F$4:$F$834 , $D$4:$D$834, "Công việc", $E$4:$E$834, "chung") | M2: =SUMIFS($F$4:$F$834 , $D$4:$D$834, "học tập", $E$4:$E$834, "chung") | N2: =SUMIFS($F$4:$F$834 , $D$4:$D$834, "đồ dùng GĐ", $E$4:$E$834, "chung") | O2: =SUMIFS($F$4:$F$834 , $D$4:$D$834, "phí tiện ích", $E$4:$E$834, "chung") | P2: =SUMIFS($F$4:$F$834 , $D$4:$D$834, "Làm đẹp", $E$4:$E$834, "chung") | Q2: =SUMIFS($F$4:$F$834 , $D$4:$D$834, "Y tế", $E$4:$E$834, "chung") | R2: =SUMIFS($F$4:$F$834 , $D$4:$D$834, "event", $E$4:$E$834, "chung") | S2: =SUMIFS($F$4:$F$834 , $D$4:$D$834, "Nợ", $E$4:$E$834, "chung")
F3: =SUM(F4:F834) | H3: Chồng | I3: =SUM(J3:S3) | J3: =SUMIFS($F$4:$F$834 , $D$4:$D$834, "Ăn uống", $E$4:$E$834, "chồng") | K3: =SUMIFS($F$4:$F$834 , $D$4:$D$834, "vui chơi", $E$4:$E$834, "chồng") | L3: =SUMIFS($F$4:$F$834 , $D$4:$D$834, "Công việc", $E$4:$E$834, "chồng") | M3: =SUMIFS($F$4:$F$834 , $D$4:$D$834, "học tập", $E$4:$E$834, "chồng") | N3: =SUMIFS($F$4:$F$834 , $D$4:$D$834, "đồ dùng GĐ", $E$4:$E$834, "chồng") | O3: =SUMIFS($F$4:$F$834 , $D$4:$D$834, "phí tiện ích", $E$4:$E$834, "chồng") | P3: =SUMIFS($F$4:$F$834 , $D$4:$D$834, "Làm đẹp", $E$4:$E$834, "chồng") | Q3: =SUMIFS($F$4:$F$834 , $D$4:$D$834, "Y tế", $E$4:$E$834, "chồng") | R3: =SUMIFS($F$4:$F$834 , $D$4:$D$834, "event", $E$4:$E$834, "chồng") | S3: =SUMIFS($F$4:$F$834 , $D$4:$D$834, "Nợ", $E$4:$E$834, "chồng")
C4: nợ ck shinhan | D4: Nợ | E4: chồng | F4: 4500000 | H4: vợ | I4: =SUM(J4:S4) | J4: =SUMIFS($F$4:$F$834 , $D$4:$D$834, "Ăn uống", $E$4:$E$834, "vợ") | K4: =SUMIFS($F$4:$F$834 , $D$4:$D$834, "vui chơi", $E$4:$E$834, "vợ") | L4: =SUMIFS($F$4:$F$834 , $D$4:$D$834, "Công việc", $E$4:$E$834, "vợ") | M4: =SUMIFS($F$4:$F$834 , $D$4:$D$834, "học tập", $E$4:$E$834, "vợ") | N4: =SUMIFS($F$4:$F$834 , $D$4:$D$834, "đồ dùng GĐ", $E$4:$E$834, "vợ") | O4: =SUMIFS($F$4:$F$834 , $D$4:$D$834, "phí tiện ích", $E$4:$E$834, "vợ") | P4: =SUMIFS($F$4:$F$834 , $D$4:$D$834, "Làm đẹp", $E$4:$E$834, "vợ") | Q4: =SUMIFS($F$4:$F$834 , $D$4:$D$834, "Y tế", $E$4:$E$834, "vợ") | R4: =SUMIFS($F$4:$F$834 , $D$4:$D$834, "event", $E$4:$E$834, "vợ") | S4: =SUMIFS($F$4:$F$834 , $D$4:$D$834, "Nợ", $E$4:$E$834, "vợ")
C5: nợ thuế ck | D5: Nợ | E5: chồng | F5: 3000000 | H5: subo | I5: =SUM(J5:S5) | J5: =SUMIFS($F$4:$F$834 , $D$4:$D$834, "Ăn uống", $E$4:$E$834, "SUBO") | K5: =SUMIFS($F$4:$F$834 , $D$4:$D$834, "vui chơi", $E$4:$E$834, "SUBO") | L5: =SUMIFS($F$4:$F$834 , $D$4:$D$834, "Công việc", $E$4:$E$834, "SUBO") | M5: =SUMIFS($F$4:$F$834 , $D$4:$D$834, "học tập", $E$4:$E$834, "SUBO") | N5: =SUMIFS($F$4:$F$834 , $D$4:$D$834, "đồ dùng GĐ", $E$4:$E$834, "SUBO") | O5: =SUMIFS($F$4:$F$834 , $D$4:$D$834, "phí tiện ích", $E$4:$E$834, "SUBO") | P5: =SUMIFS($F$4:$F$834 , $D$4:$D$834, "Làm đẹp", $E$4:$E$834, "SUBO") | Q5: =SUMIFS($F$4:$F$834 , $D$4:$D$834, "Y tế", $E$4:$E$834, "SUBO") | R5: =SUMIFS($F$4:$F$834 , $D$4:$D$834, "event", $E$4:$E$834, "SUBO") | S5: =SUMIFS($F$4:$F$834 , $D$4:$D$834, "Nợ", $E$4:$E$834, "SUBO")
C6: nợ đt vk | D6: Nợ | E6: vợ | F6: 3000000 | H6: sugi | I6: =SUM(J6:S6) | J6: =SUMIFS($F$4:$F$834 , $D$4:$D$834, "Ăn uống", $E$4:$E$834, "SUGI") | K6: =SUMIFS($F$4:$F$834 , $D$4:$D$834, "vui chơi", $E$4:$E$834, "SUGI") | L6: =SUMIFS($F$4:$F$834 , $D$4:$D$834, "Công việc", $E$4:$E$834, "SUGI") | M6: =SUMIFS($F$4:$F$834 , $D$4:$D$834, "học tập", $E$4:$E$834, "SUGI") | N6: =SUMIFS($F$4:$F$834 , $D$4:$D$834, "đồ dùng GĐ", $E$4:$E$834, "SUGI") | O6: =SUMIFS($F$4:$F$834 , $D$4:$D$834, "phí tiện ích", $E$4:$E$834, "SUGI") | P6: =SUMIFS($F$4:$F$834 , $D$4:$D$834, "Làm đẹp", $E$4:$E$834, "SUGI") | Q6: =SUMIFS($F$4:$F$834 , $D$4:$D$834, "Y tế", $E$4:$E$834, "SUGI") | R6: =SUMIFS($F$4:$F$834 , $D$4:$D$834, "event", $E$4:$E$834, "SUGI") | S6: =SUMIFS($F$4:$F$834 , $D$4:$D$834, "Nợ", $E$4:$E$834, "SUGI")
C7: học phí subo | D7: học tập | E7: SUBO | F7: =9350000+2520000 | I7: sum | J7: =SUM(J2:J6) | K7: =SUM(K2:K6) | L7: =SUM(L2:L6) | M7: =SUM(M2:M6) | N7: =SUM(N2:N6) | O7: =SUM(O2:O6) | P7: =SUM(P2:P6) | Q7: =SUM(Q2:Q6) | ... S7: =SUM(S2:S6)
C8: coop | D8: Ăn uống | E8: Chung | F8: =506000+810000+813000 | I8: % | J8: =J7/$I$1 | K8: =K7/$I$1 | L8: =L7/$I$1 | M8: =M7/$I$1 | N8: =N7/$I$1 | O8: =O7/$I$1 | P8: =P7/$I$1 | Q8: =Q7/$I$1 | ... S8: =S7/$I$1
C9: rút tiền mặt. | D9: Ăn uống | E9: Chung | F9: 3000000
C10: tiền học shopee | D10: học tập | E10: vợ | F10: 4686000
C11: ví vk | D11: Làm đẹp | E11: vợ | F11: 14000 | V11: =J4/14
C12: grab lên bà hằng | D12: phí tiện ích | E12: Chung | F12: 25000
C13: khu vui chơi | D13: vui chơi | E13: SUBO | F13: 75000 | V13: =J3/14
C14: ăn ck mời đn | D14: Ăn uống | E14: chồng | F14: 226000
C15: phí qlcc | D15: phí tiện ích | E15: Chung | F15: 691000
C16: chôm chôm, cua xay | D16: Ăn uống | E16: Chung | F16: =40000+54000
C17: mua sim | D17: Công việc | E17: Chung | F17: 185000
C18: spee thuốc bổ | D18: Y tế | E18: Chung | F18: 998000
C19: spee áo khoác nắng | D19: Làm đẹp | E19: vợ | F19: 490000
C20: spee khẩu trang | D20: Y tế | E20: Chung | F20: 231000
C21: spee que test tiểu đường | D21: Y tế | E21: Chung | F21: 286000
C22: spee sữa | D22: Ăn uống | E22: Chung | F22: 444000
C23: spee quần mưa, trùm balo | D23: đồ dùng GĐ | E23: chồng | F23: =45000+125000
C24: spee kem hăm | D24: đồ dùng GĐ | E24: SUGI | F24: 240000
C25: spee bình sữa | D25: đồ dùng GĐ | E25: SUGI | F25: 646000
C26: chat gpt | D26: Công việc | E26: Chung | F26: =46190000-45600000
C27: internet | D27: phí tiện ích | E27: Chung | F27: 220000
C28: tiền điện | D28: phí tiện ích | E28: Chung | F28: 1807000
C29: winmart, coop | D29: Ăn uống | E29: Chung | F29: =16000+38000+82000+50000
C30: đi chợ(bánh mì, chôm2, bánh trung thu) | D30: Ăn uống | E30: Chung | F30: =7000+75000+290000
C31: rút | D31: Ăn uống | E31: Chung | F31: 3000000
C32: win mart | D32: Ăn uống | E32: Chung | F32: =35000+21000+150000+290000
C33: spee nguyen lieu lam banh | D33: Ăn uống | E33: Chung | F33: =101000+167000+45000+62000+81000+146000+138000+24000
C34: spee đồ dùng ( cân,... | D34: đồ dùng GĐ | E34: Chung | F34: =37000+62000+168000+159000+133000+260000+169000
C35: spee vit D | D35: Y tế | E35: SUGI | F35: 369000
C36: xăng vk | D36: phí tiện ích | E36: vợ | F36: 80000
C37: donut | D37: Ăn uống | E37: Chung | F37: 80000
C38: làm nách vk | D38: Làm đẹp | E38: vợ | F38: 20000000
C39: winmart | D39: Ăn uống | E39: Chung | F39: =68000+24000
C40: you tube | D40: phí tiện ích | E40: chồng | F40: 88000
...

Sheet T6 - MASTER
B1: 46023
A3: I | B3: THU NHẬP | C3: 1 | D3: =SUM(D4:D7)
A4: 1 | B4: ck | D4: =SUM(E4:H4) | E4: 44947000 | F4: 8000000 | G4: 0 | H4: 0
A5: 2 | B5: vk | D5: =SUM(E5:H5) | E5: 30000000 | F5: 5000000 | G5: 0 | H5: 0
A6: 3 | B6: Subo | D6: =SUM(E6:H6) | E6: 500000 | F6: 200000 | G6: 0 | H6: 0
A7: 4 | B7: Sugi | D7: =SUM(E7:H7) | E7: 500000 | F7: 200000 | G7: 400000 | H7: 0
A8: II | B8: TIẾT KIỆM | C8: 0.3 | D8: =D3*C8 | I8: CÒN LẠI | K8: =D3-D11
B9: TK thực tế | I9: CP ĐÃ TRỪ NHƯNG CHƯA ĐÓNG | J9: HỌC PHÍ
A10: III | B10: CHI PHÍ | C10: 0.7 | D10: =D3*C10 | J10: ĐIỆN THOẠI
B11: CP Thực tế | D11: =SUM(D12,D16,D18) | K11: =SUM(K8:K10)
A12: 1 | B12: Chi phí chung gia đình | C12: =IFERROR(D12/D11, 0) | D12: =SUM(D13:D15)
A13: a | B13: Chi phí chung | C13: =IFERROR(D13/$D$10, 0) | D13: ='T6 - DETAIL'!I2
A14: b | B14: Chi phí riêng subo | C14: =IFERROR(D14/$D$10, 0) | D14: ='T6 - DETAIL'!I5
A15: c | B15: chi phí riêng sugi | C15: =IFERROR(D15/$D$10, 0) | D15: ='T6 - DETAIL'!I6
A16: 2 | B16: Chi phí riêng ck (30%) | C16: =IFERROR(D16/D11, 0) | D16: ='T6 - DETAIL'!I3
B17: =30%*D10
A18: 3 | B18: Chi phí riêng vk (30%) | C18: =IFERROR(D18/D11, 0) | D18: ='T6 - DETAIL'!I4
B19: =30%*D10

Sheet T6 - DETAIL
H1: Tổng | I1: =SUM(F4:F1015) | J1: ăn uống | K1: vui chơi | L1: công việc | M1: học tập | N1: đồ dùng GĐ | O1: Phí tiện ích | P1: làm đẹp | Q1: y tế | R1: event | S1: nợ
B2: Ngày | C2: nội dung | D2: Hạng mục | E2: Phân loại | F2: Số Tiền | H2: Chung | I2: =SUM(J2:S2) | J2: =SUMIFS($F$4:$F$834 , $D$4:$D$834, "Ăn uống", $E$4:$E$834, "chung") | K2: =SUMIFS($F$4:$F$834 , $D$4:$D$834, "vui chơi", $E$4:$E$834, "chung") | L2: =SUMIFS($F$4:$F$834 , $D$4:$D$834, "Công việc", $E$4:$E$834, "chung") | M2: =SUMIFS($F$4:$F$834 , $D$4:$D$834, "học tập", $E$4:$E$834, "chung") | N2: =SUMIFS($F$4:$F$834 , $D$4:$D$834, "đồ dùng GĐ", $E$4:$E$834, "chung") | O2: =SUMIFS($F$4:$F$834 , $D$4:$D$834, "phí tiện ích", $E$4:$E$834, "chung") | P2: =SUMIFS($F$4:$F$834 , $D$4:$D$834, "Làm đẹp", $E$4:$E$834, "chung") | Q2: =SUMIFS($F$4:$F$834 , $D$4:$D$834, "Y tế", $E$4:$E$834, "chung") | R2: =SUMIFS($F$4:$F$834 , $D$4:$D$834, "event", $E$4:$E$834, "chung") | S2: =SUMIFS($F$4:$F$834 , $D$4:$D$834, "Nợ", $E$4:$E$834, "chung")
